Workbook

Sheet Countries by Continent
A1: S. No. | B1: Country | C1: Continent | D1: Sub-Region | E1: Population (2025 est.) | F1: Population Band | G1: GDP Nominal, USD (2024) | H1: GDP per Capita, USD | I1: Income Tier | J1: African Diaspora (Yes/No) | K1: Est. African-Descent Population | L1: Diaspora Profile | M1: Diaspora Priority | N1: Landlocked | O1: ECOWAS Status | P1: AfCFTA | Q1: Trade Bloc / Market Access | R1: Business Language | S1: Notes | T1: Existing Buyer? (Y/N) | U1: Import Duty % (HS 3923/3924) | V1: Est. Annual Import Value (USD) | W1: Local Competition (H/M/L) | X1: Distributor Status | Y1: Assigned | Z1: Market Size (1-5) | AA1: Access Ease (1-5) | AB1: Diaspora Fit (1-5) | AC1: Competition (1-5) | AD1: Weighted Score | AE1: Priority Tier
A2: 41 | B2: Sao Tome and Principe | C2: Africa | D2: Middle Africa | E2: 240000 | F2: =IF($E2="","",IF($E2>=100000000,"Over 100 m",IF($E2>=25000000,"25-100 m",IF($E2>=5000000,"5-25 m",IF($E2>=1000000,"1-5 m","Under 1 m"))))) -> Under 1 m | G2: 750000000 | H2: =IF(OR($G2="",$E2="",$E2=0),"",ROUND($G2/$E2,0)) -> 3125 | I2: =IF($H2="","",IF($H2>14005,"High income",IF($H2>4515,"Upper-middle",IF($H2>1145,"Lower-middle","Low income")))) -> Lower-middle | J2: Home | K2: Source continent | L2: Home market - not diaspora; served directly by SACVIN Nigeria / AfCFTA | M2: Home | N2: No | O2: Non-member | P2: Signatory | Q2: AfCFTA | R2: Portuguese | Y2: =IF($C2="Africa","Manan",IF(OR($C2="Europe",$C2="South America",$C2="Oceania"),"Dev","Aditya")) -> Manan | AB2: =IF($M2="High",5,IF($M2="Medium",3,IF($M2="Home",4,IF($M2="Low",1,0)))) -> 4 | AD2: =IF(COUNT(Z2,AA2,AC2)=0,"",ROUND(Z2*'Scoring Guide'!$B$5+AA2*'Scoring Guide'!$B$6+AB2*'Scoring Guide'!$B$7+AC2*'Scoring Guide'!$B$8,2)) | AE2: =IF(AD2="","Not scored",IF(AD2>='Scoring Guide'!$B$11,"Tier 1 - Priority",IF(AD2>='Scoring Guide'!$B$12,"Tier 2 - Develop",IF(AD2>='Scoring Guide'!$B$13,"Tier 3 - Monitor","Tier 4 - Deprioritise")))) -> Not scored
A3: 11 | B3: Comoros | C3: Africa | D3: Eastern Africa | E3: 880000 | F3: =IF($E3="","",IF($E3>=100000000,"Over 100 m",IF($E3>=25000000,"25-100 m",IF($E3>=5000000,"5-25 m",IF($E3>=1000000,"1-5 m","Under 1 m"))))) -> Under 1 m | G3: 1400000000 | H3: =IF(OR($G3="",$E3="",$E3=0),"",ROUND($G3/$E3,0)) -> 1591 | I3: =IF($H3="","",IF($H3>14005,"High income",IF($H3>4515,"Upper-middle",IF($H3>1145,"Lower-middle","Low income")))) -> Lower-middle | J3: Home | K3: Source continent | L3: Home market - not diaspora; served directly by SACVIN Nigeria / AfCFTA | M3: Home | N3: No | O3: Non-member | P3: Signatory | Q3: AfCFTA | R3: Arabic / French | Y3: =IF($C3="Africa","Manan",IF(OR($C3="Europe",$C3="South America",$C3="Oceania"),"Dev","Aditya")) -> Manan | AB3: =IF($M3="High",5,IF($M3="Medium",3,IF($M3="Home",4,IF($M3="Low",1,0)))) -> 4 | AD3: =IF(COUNT(Z3,AA3,AC3)=0,"",ROUND(Z3*'Scoring Guide'!$B$5+AA3*'Scoring Guide'!$B$6+AB3*'Scoring Guide'!$B$7+AC3*'Scoring Guide'!$B$8,2)) | AE3: =IF(AD3="","Not scored",IF(AD3>='Scoring Guide'!$B$11,"Tier 1 - Priority",IF(AD3>='Scoring Guide'!$B$12,"Tier 2 - Develop",IF(AD3>='Scoring Guide'!$B$13,"Tier 3 - Monitor","Tier 4 - Deprioritise")))) -> Not scored
A4: 43 | B4: Seychelles | C4: Africa | D4: Eastern Africa | E4: 130000 | F4: =IF($E4="","",IF($E4>=100000000,"Over 100 m",IF($E4>=25000000,"25-100 m",IF($E4>=5000000,"5-25 m",IF($E4>=1000000,"1-5 m","Under 1 m"))))) -> Under 1 m | G4: 2200000000 | H4: =IF(OR($G4="",$E4="",$E4=0),"",ROUND($G4/$E4,0)) -> 16923 | I4: =IF($H4="","",IF($H4>14005,"High income",IF($H4>4515,"Upper-middle",IF($H4>1145,"Lower-middle","Low income")))) -> High income | J4: Home | K4: Source continent | L4: Home market - not diaspora; served directly by SACVIN Nigeria / AfCFTA | M4: Home | N4: No | O4: Non-member | P4: Signatory | Q4: AfCFTA | R4: French / English | Y4: =IF($C4="Africa","Manan",IF(OR($C4="Europe",$C4="South America",$C4="Oceania"),"Dev","Aditya")) -> Manan | AB4: =IF($M4="High",5,IF($M4="Medium",3,IF($M4="Home",4,IF($M4="Low",1,0)))) -> 4 | AD4: =IF(COUNT(Z4,AA4,AC4)=0,"",ROUND(Z4*'Scoring Guide'!$B$5+AA4*'Scoring Guide'!$B$6+AB4*'Scoring Guide'!$B$7+AC4*'Scoring Guide'!$B$8,2)) | AE4: =IF(AD4="","Not scored",IF(AD4>='Scoring Guide'!$B$11,"Tier 1 - Priority",IF(AD4>='Scoring Guide'!$B$12,"Tier 2 - Develop",IF(AD4>='Scoring Guide'!$B$13,"Tier 3 - Monitor","Tier 4 - Deprioritise")))) -> Not scored
A5: 7 | B5: Cabo Verde | C5: Africa | D5: Western Africa | E5: 530000 | F5: =IF($E5="","",IF($E5>=100000000,"Over 100 m",IF($E5>=25000000,"25-100 m",IF($E5>=5000000,"5-25 m",IF($E5>=1000000,"1-5 m","Under 1 m"))))) -> Under 1 m | G5: 2800000000 | H5: =IF(OR($G5="",$E5="",$E5=0),"",ROUND($G5/$E5,0)) -> 5283 | I5: =IF($H5="","",IF($H5>14005,"High income",IF($H5>4515,"Upper-middle",IF($H5>1145,"Lower-middle","Low income")))) -> Upper-middle | J5: Home | K5: Source continent | L5: Home market - not diaspora; served directly by SACVIN Nigeria / AfCFTA | M5: Home | N5: No | O5: Member | P5: Signatory | Q5: AfCFTA | R5: Portuguese | Y5: =IF($C5="Africa","Manan",IF(OR($C5="Europe",$C5="South America",$C5="Oceania"),"Dev","Aditya")) -> Manan | AB5: =IF($M5="High",5,IF($M5="Medium",3,IF($M5="Home",4,IF($M5="Low",1,0)))) -> 4 | AD5: =IF(COUNT(Z5,AA5,AC5)=0,"",ROUND(Z5*'Scoring Guide'!$B$5+AA5*'Scoring Guide'!$B$6+AB5*'Scoring Guide'!$B$7+AC5*'Scoring Guide'!$B$8,2)) | AE5: =IF(AD5="","Not scored",IF(AD5>='Scoring Guide'!$B$11,"Tier 1 - Priority",IF(AD5>='Scoring Guide'!$B$12,"Tier 2 - Develop",IF(AD5>='Scoring Guide'!$B$13,"Tier 3 - Monitor","Tier 4 - Deprioritise")))) -> Not scored
A6: 12 | B6: Congo (Democratic Republic of the) | C6: Africa | D6: Middle Africa | E6: 112000000 | F6: =IF($E6="","",IF($E6>=100000000,"Over 100 m",IF($E6>=25000000,"25-100 m",IF($E6>=5000000,"5-25 m",IF($E6>=1000000,"1-5 m","Under 1 m"))))) -> Over 100 m | G6: 75000000000 | H6: =IF(OR($G6="",$E6="",$E6=0),"",ROUND($G6/$E6,0)) -> 670 | I6: =IF($H6="","",IF($H6>14005,"High income",IF($H6>4515,"Upper-middle",IF($H6>1145,"Lower-middle","Low income")))) -> Low income | J6: Home | K6: Source continent | L6: Home market - not diaspora; served directly by SACVIN Nigeria / AfCFTA | M6: Home | N6: No | O6: Non-member | P6: Signatory | Q6: AfCFTA | R6: French | Y6: =IF($C6="Africa","Manan",IF(OR($C6="Europe",$C6="South America",$C6="Oceania"),"Dev","Aditya")) -> Manan | AB6: =IF($M6="High",5,IF($M6="Medium",3,IF($M6="Home",4,IF($M6="Low",1,0)))) -> 4 | AD6: =IF(COUNT(Z6,AA6,AC6)=0,"",ROUND(Z6*'Scoring Guide'!$B$5+AA6*'Scoring Guide'!$B$6+AB6*'Scoring Guide'!$B$7+AC6*'Scoring Guide'!$B$8,2)) | AE6: =IF(AD6="","Not scored",IF(AD6>='Scoring Guide'!$B$11,"Tier 1 - Priority",IF(AD6>='Scoring Guide'!$B$12,"Tier 2 - Develop",IF(AD6>='Scoring Guide'!$B$13,"Tier 3 - Monitor","Tier 4 - Deprioritise")))) -> Not scored
A7: 20 | B7: Ethiopia | C7: Africa | D7: Eastern Africa | E7: 135000000 | F7: =IF($E7="","",IF($E7>=100000000,"Over 100 m",IF($E7>=25000000,"25-100 m",IF($E7>=5000000,"5-25 m",IF($E7>=1000000,"1-5 m","Under 1 m"))))) -> Over 100 m | G7: 145000000000 | H7: =IF(OR($G7="",$E7="",$E7=0),"",ROUND($G7/$E7,0)) -> 1074 | I7: =IF($H7="","",IF($H7>14005,"High income",IF($H7>4515,"Upper-middle",IF($H7>1145,"Lower-middle","Low income")))) -> Low income | J7: Home | K7: Source continent | L7: Home market - not diaspora; served directly by SACVIN Nigeria / AfCFTA | M7: Home | N7: Yes | O7: Non-member | P7: Signatory | Q7: AfCFTA | R7: English | Y7: =IF($C7="Africa","Manan",IF(OR($C7="Europe",$C7="South America",$C7="Oceania"),"Dev","Aditya")) -> Manan | AB7: =IF($M7="High",5,IF($M7="Medium",3,IF($M7="Home",4,IF($M7="Low",1,0)))) -> 4 | AD7: =IF(COUNT(Z7,AA7,AC7)=0,"",ROUND(Z7*'Scoring Guide'!$B$5+AA7*'Scoring Guide'!$B$6+AB7*'Scoring Guide'!$B$7+AC7*'Scoring Guide'!$B$8,2)) | AE7: =IF(AD7="","Not scored",IF(AD7>='Scoring Guide'!$B$11,"Tier 1 - Priority",IF(AD7>='Scoring Guide'!$B$12,"Tier 2 - Develop",IF(AD7>='Scoring Guide'!$B$13,"Tier 3 - Monitor","Tier 4 - Deprioritise")))) -> Not scored
A8: 16 | B8: Egypt | C8: Africa | D8: Northern Africa | E8: 118000000 | F8: =IF($E8="","",IF($E8>=100000000,"Over 100 m",IF($E8>=25000000,"25-100 m",IF($E8>=5000000,"5-25 m",IF($E8>=1000000,"1-5 m","Under 1 m"))))) -> Over 100 m | G8: 380000000000 | H8: =IF(OR($G8="",$E8="",$E8=0),"",ROUND($G8/$E8,0)) -> 3220 | I8: =IF($H8="","",IF($H8>14005,"High income",IF($H8>4515,"Upper-middle",IF($H8>1145,"Lower-middle","Low income")))) -> Lower-middle | J8: Home | K8: Source continent | L8: Home market - not diaspora; served directly by SACVIN Nigeria / AfCFTA | M8: Home | N8: No | O8: Non-member | P8: Signatory | Q8: AfCFTA | R8: Arabic / English | S8: Transcontinental - Sinai Peninsula lies in Asia | Y8: =IF($C8="Africa","Manan",IF(OR($C8="Europe",$C8="South America",$C8="Oceania"),"Dev","Aditya")) -> Manan | AB8: =IF($M8="High",5,IF($M8="Medium",3,IF($M8="Home",4,IF($M8="Low",1,0)))) -> 4 | AD8: =IF(COUNT(Z8,AA8,AC8)=0,"",ROUND(Z8*'Scoring Guide'!$B$5+AA8*'Scoring Guide'!$B$6+AB8*'Scoring Guide'!$B$7+AC8*'Scoring Guide'!$B$8,2)) | AE8: =IF(AD8="","Not scored",IF(AD8>='Scoring Guide'!$B$11,"Tier 1 - Priority",IF(AD8>='Scoring Guide'!$B$12,"Tier 2 - Develop",IF(AD8>='Scoring Guide'!$B$13,"Tier 3 - Monitor","Tier 4 - Deprioritise")))) -> Not scored
A9: 6 | B9: Burundi | C9: Africa | D9: Eastern Africa | E9: 14400000 | F9: =IF($E9="","",IF($E9>=100000000,"Over 100 m",IF($E9>=25000000,"25-100 m",IF($E9>=5000000,"5-25 m",IF($E9>=1000000,"1-5 m","Under 1 m"))))) -> 5-25 m | G9: 2600000000 | H9: =IF(OR($G9="",$E9="",$E9=0),"",ROUND($G9/$E9,0)) -> 181 | I9: =IF($H9="","",IF($H9>14005,"High income",IF($H9>4515,"Upper-middle",IF($H9>1145,"Lower-middle","Low income")))) -> Low income | J9: Home | K9: Source continent | L9: Home market - not diaspora; served directly by SACVIN Nigeria / AfCFTA | M9: Home | N9: Yes | O9: Non-member | P9: Signatory | Q9: AfCFTA | R9: French | Y9: =IF($C9="Africa","Manan",IF(OR($C9="Europe",$C9="South America",$C9="Oceania"),"Dev","Aditya")) -> Manan | AB9: =IF($M9="High",5,IF($M9="Medium",3,IF($M9="Home",4,IF($M9="Low",1,0)))) -> 4 | AD9: =IF(COUNT(Z9,AA9,AC9)=0,"",ROUND(Z9*'Scoring Guide'!$B$5+AA9*'Scoring Guide'!$B$6+AB9*'Scoring Guide'!$B$7+AC9*'Scoring Guide'!$B$8,2)) | AE9: =IF(AD9="","Not scored",IF(AD9>='Scoring Guide'!$B$11,"Tier 1 - Priority",IF(AD9>='Scoring Guide'!$B$12,"Tier 2 - Develop",IF(AD9>='Scoring Guide'!$B$13,"Tier 3 - Monitor","Tier 4 - Deprioritise")))) -> Not scored
A10: 9 | B10: Central African Republic | C10: Africa | D10: Middle Africa | E10: 5700000 | F10: =IF($E10="","",IF($E10>=100000000,"Over 100 m",IF($E10>=25000000,"25-100 m",IF($E10>=5000000,"5-25 m",IF($E10>=1000000,"1-5 m","Under 1 m"))))) -> 5-25 m | G10: 2800000000 | H10: =IF(OR($G10="",$E10="",$E10=0),"",ROUND($G10/$E10,0)) -> 491 | I10: =IF($H10="","",IF($H10>14005,"High income",IF($H10>4515,"Upper-middle",IF($H10>1145,"Lower-middle","Low income")))) -> Low income | J10: Home | K10: Source continent | L10: Home market - not diaspora; served directly by SACVIN Nigeria / AfCFTA | M10: Home | N10: Yes | O10: Non-member | P10: Signatory | Q10: AfCFTA | R10: French | Y10: =IF($C10="Africa","Manan",IF(OR($C10="Europe",$C10="South America",$C10="Oceania"),"Dev","Aditya")) -> Manan | AB10: =IF($M10="High",5,IF($M10="Medium",3,IF($M10="Home",4,IF($M10="Low",1,0)))) -> 4 | AD10: =IF(COUNT(Z10,AA10,AC10)=0,"",ROUND(Z10*'Scoring Guide'!$B$5+AA10*'Scoring Guide'!$B$6+AB10*'Scoring Guide'!$B$7+AC10*'Scoring Guide'!$B$8,2)) | AE10: =IF(AD10="","Not scored",IF(AD10>='Scoring Guide'!$B$11,"Tier 1 - Priority",IF(AD10>='Scoring Guide'!$B$12,"Tier 2 - Develop",IF(AD10>='Scoring Guide'!$B$13,"Tier 3 - Monitor","Tier 4 - Deprioritise")))) -> Not scored
A11: 28 | B11: Liberia | C11: Africa | D11: Western Africa | E11: 5700000 | F11: =IF($E11="","",IF($E11>=100000000,"Over 100 m",IF($E11>=25000000,"25-100 m",IF($E11>=5000000,"5-25 m",IF($E11>=1000000,"1-5 m","Under 1 m"))))) -> 5-25 m | G11: 4600000000 | H11: =IF(OR($G11="",$E11="",$E11=0),"",ROUND($G11/$E11,0)) -> 807 | I11: =IF($H11="","",IF($H11>14005,"High income",IF($H11>4515,"Upper-middle",IF($H11>1145,"Lower-middle","Low income")))) -> Low income | J11: Home | K11: Source continent | L11: Home market - not diaspora; served directly by SACVIN Nigeria / AfCFTA | M11: Home | N11: No | O11: Member | P11: Signatory | Q11: AfCFTA | R11: English | Y11: =IF($C11="Africa","Manan",IF(OR($C11="Europe",$C11="South America",$C11="Oceania"),"Dev","Aditya")) -> Manan | AB11: =IF($M11="High",5,IF($M11="Medium",3,IF($M11="Home",4,IF($M11="Low",1,0)))) -> 4 | AD11: =IF(COUNT(Z11,AA11,AC11)=0,"",ROUND(Z11*'Scoring Guide'!$B$5+AA11*'Scoring Guide'!$B$6+AB11*'Scoring Guide'!$B$7+AC11*'Scoring Guide'!$B$8,2)) | AE11: =IF(AD11="","Not scored",IF(AD11>='Scoring Guide'!$B$11,"Tier 1 - Priority",IF(AD11>='Scoring Guide'!$B$12,"Tier 2 - Develop",IF(AD11>='Scoring Guide'!$B$13,"Tier 3 - Monitor","Tier 4 - Deprioritise")))) -> Not scored
A12: 47 | B12: South Sudan | C12: Africa | D12: Eastern Africa | E12: 12000000 | F12: =IF($E12="","",IF($E12>=100000000,"Over 100 m",IF($E12>=25000000,"25-100 m",IF($E12>=5000000,"5-25 m",IF($E12>=1000000,"1-5 m","Under 1 m"))))) -> 5-25 m | G12: 6000000000 | H12: =IF(OR($G12="",$E12="",$E12=0),"",ROUND($G12/$E12,0)) -> 500 | I12: =IF($H12="","",IF($H12>14005,"High income",IF($H12>4515,"Upper-middle",IF($H12>1145,"Lower-middle","Low income")))) -> Low income | J12: Home | K12: Source continent | L12: Home market - not diaspora; served directly by SACVIN Nigeria / AfCFTA | M12: Home | N12: Yes | O12: Non-member | P12: Signatory | Q12: AfCFTA | R12: English | Y12: =IF($C12="Africa","Manan",IF(OR($C12="Europe",$C12="South America",$C12="Oceania"),"Dev","Aditya")) -> Manan | AB12: =IF($M12="High",5,IF($M12="Medium",3,IF($M12="Home",4,IF($M12="Low",1,0)))) -> 4 | AD12: =IF(COUNT(Z12,AA12,AC12)=0,"",ROUND(Z12*'Scoring Guide'!$B$5+AA12*'Scoring Guide'!$B$6+AB12*'Scoring Guide'!$B$7+AC12*'Scoring Guide'!$B$8,2)) | AE12: =IF(AD12="","Not scored",IF(AD12>='Scoring Guide'!$B$11,"Tier 1 - Priority",IF(AD12>='Scoring Guide'!$B$12,"Tier 2 - Develop",IF(AD12>='Scoring Guide'!$B$13,"Tier 3 - Monitor","Tier 4 - Deprioritise")))) -> Not scored
A13: 44 | B13: Sierra Leone | C13: Africa | D13: Western Africa | E13: 8900000 | F13: =IF($E13="","",IF($E13>=100000000,"Over 100 m",IF($E13>=25000000,"25-100 m",IF($E13>=5000000,"5-25 m",IF($E13>=1000000,"1-5 m","Under 1 m"))))) -> 5-25 m | G13: 6400000000 | H13: =IF(OR($G13="",$E13="",$E13=0),"",ROUND($G13/$E13,0)) -> 719 | I13: =IF($H13="","",IF($H13>14005,"High income",IF($H13>4515,"Upper-middle",IF($H13>1145,"Lower-middle","Low income")))) -> Low income | J13: Home | K13: Source continent | L13: Home market - not diaspora; served directly by SACVIN Nigeria / AfCFTA | M13: Home | N13: No | O13: Member | P13: Signatory | Q13: AfCFTA | R13: English | Y13: =IF($C13="Africa","Manan",IF(OR($C13="Europe",$C13="South America",$C13="Oceania"),"Dev","Aditya")) -> Manan | AB13: =IF($M13="High",5,IF($M13="Medium",3,IF($M13="Home",4,IF($M13="Low",1,0)))) -> 4 | AD13: =IF(COUNT(Z13,AA13,AC13)=0,"",ROUND(Z13*'Scoring Guide'!$B$5+AA13*'Scoring Guide'!$B$6+AB13*'Scoring Guide'!$B$7+AC13*'Scoring Guide'!$B$8,2)) | AE13: =IF(AD13="","Not scored",IF(AD13>='Scoring Guide'!$B$11,"Tier 1 - Priority",IF(AD13>='Scoring Guide'!$B$12,"Tier 2 - Develop",IF(AD13>='Scoring Guide'!$B$13,"Tier 3 - Monitor","Tier 4 - Deprioritise")))) -> Not scored
A14: 50 | B14: Togo | C14: Africa | D14: Western Africa | E14: 9800000 | F14: =IF($E14="","",IF($E14>=100000000,"Over 100 m",IF($E14>=25000000,"25-100 m",IF($E14>=5000000,"5-25 m",IF($E14>=1000000,"1-5 m","Under 1 m"))))) -> 5-25 m | G14: 9500000000 | H14: =IF(OR($G14="",$E14="",$E14=0),"",ROUND($G14/$E14,0)) -> 969 | I14: =IF($H14="","",IF($H14>14005,"High income",IF($H14>4515,"Upper-middle",IF($H14>1145,"Lower-middle","Low income")))) -> Low income | J14: Home | K14: Source continent | L14: Home market - not diaspora; served directly by SACVIN Nigeria / AfCFTA | M14: Home | N14: No | O14: Member | P14: Signatory | Q14: AfCFTA | R14: French | Y14: =IF($C14="Africa","Manan",IF(OR($C14="Europe",$C14="South America",$C14="Oceania"),"Dev","Aditya")) -> Manan | AB14: =IF($M14="High",5,IF($M14="Medium",3,IF($M14="Home",4,IF($M14="Low",1,0)))) -> 4 | AD14: =IF(COUNT(Z14,AA14,AC14)=0,"",ROUND(Z14*'Scoring Guide'!$B$5+AA14*'Scoring Guide'!$B$6+AB14*'Scoring Guide'!$B$7+AC14*'Scoring Guide'!$B$8,2)) | AE14: =IF(AD14="","Not scored",IF(AD14>='Scoring Guide'!$B$11,"Tier 1 - Priority",IF(AD14>='Scoring Guide'!$B$12,"Tier 2 - Develop",IF(AD14>='Scoring Guide'!$B$13,"Tier 3 - Monitor","Tier 4 - Deprioritise")))) -> Not scored
A15: 33 | B15: Mauritania | C15: Africa | D15: Western Africa | E15: 5300000 | F15: =IF($E15="","",IF($E15>=100000000,"Over 100 m",IF($E15>=25000000,"25-100 m",IF($E15>=5000000,"5-25 m",IF($E15>=1000000,"1-5 m","Under 1 m"))))) -> 5-25 m | G15: 11100000000 | H15: =IF(OR($G15="",$E15="",$E15=0),"",ROUND($G15/$E15,0)) -> 2094 | I15: =IF($H15="","",IF($H15>14005,"High income",IF($H15>4515,"Upper-middle",IF($H15>1145,"Lower-middle","Low income")))) -> Lower-middle | J15: Home | K15: Source continent | L15: Home market - not diaspora; served directly by SACVIN Nigeria / AfCFTA | M15: Home | N15: No | O15: Non-member | P15: Signatory | Q15: AfCFTA | R15: Arabic / French | Y15: =IF($C15="Africa","Manan",IF(OR($C15="Europe",$C15="South America",$C15="Oceania"),"Dev","Aditya")) -> Manan | AB15: =IF($M15="High",5,IF($M15="Medium",3,IF($M15="Home",4,IF($M15="Low",1,0)))) -> 4 | AD15: =IF(COUNT(Z15,AA15,AC15)=0,"",ROUND(Z15*'Scoring Guide'!$B$5+AA15*'Scoring Guide'!$B$6+AB15*'Scoring Guide'!$B$7+AC15*'Scoring Guide'!$B$8,2)) | AE15: =IF(AD15="","Not scored",IF(AD15>='Scoring Guide'!$B$11,"Tier 1 - Priority",IF(AD15>='Scoring Guide'!$B$12,"Tier 2 - Develop",IF(AD15>='Scoring Guide'!$B$13,"Tier 3 - Monitor","Tier 4 - Deprioritise")))) -> Not scored
A16: 31 | B16: Malawi | C16: Africa | D16: Eastern Africa | E16: 22000000 | F16: =IF($E16="","",IF($E16>=100000000,"Over 100 m",IF($E16>=25000000,"25-100 m",IF($E16>=5000000,"5-25 m",IF($E16>=1000000,"1-5 m","Under 1 m"))))) -> 5-25 m | G16: 11800000000 | H16: =IF(OR($G16="",$E16="",$E16=0),"",ROUND($G16/$E16,0)) -> 536 | I16: =IF($H16="","",IF($H16>14005,"High income",IF($H16>4515,"Upper-middle",IF($H16>1145,"Lower-middle","Low income")))) -> Low income | J16: Home | K16: Source continent | L16: Home market - not diaspora; served directly by SACVIN Nigeria / AfCFTA | M16: Home | N16: Yes | O16: Non-member | P16: Signatory | Q16: AfCFTA | R16: English | Y16: =IF($C16="Africa","Manan",IF(OR($C16="Europe",$C16="South America",$C16="Oceania"),"Dev","Aditya")) -> Manan | AB16: =IF($M16="High",5,IF($M16="Medium",3,IF($M16="Home",4,IF($M16="Low",1,0)))) -> 4 | AD16: =IF(COUNT(Z16,AA16,AC16)=0,"",ROUND(Z16*'Scoring Guide'!$B$5+AA16*'Scoring Guide'!$B$6+AB16*'Scoring Guide'!$B$7+AC16*'Scoring Guide'!$B$8,2)) | AE16: =IF(AD16="","Not scored",IF(AD16>='Scoring Guide'!$B$11,"Tier 1 - Priority",IF(AD16>='Scoring Guide'!$B$12,"Tier 2 - Develop",IF(AD16>='Scoring Guide'!$B$13,"Tier 3 - Monitor","Tier 4 - Deprioritise")))) -> Not scored
A17: 45 | B17: Somalia | C17: Africa | D17: Eastern Africa | E17: 19600000 | F17: =IF($E17="","",IF($E17>=100000000,"Over 100 m",IF($E17>=25000000,"25-100 m",IF($E17>=5000000,"5-25 m",IF($E17>=1000000,"1-5 m","Under 1 m"))))) -> 5-25 m | G17: 12000000000 | H17: =IF(OR($G17="",$E17="",$E17=0),"",ROUND($G17/$E17,0)) -> 612 | I17: =IF($H17="","",IF($H17>14005,"High income",IF($H17>4515,"Upper-middle",IF($H17>1145,"Lower-middle","Low income")))) -> Low income | J17: Home | K17: Source continent | L17: Home market - not diaspora; served directly by SACVIN Nigeria / AfCFTA | M17: Home | N17: No | O17: Non-member | P17: Signatory | Q17: AfCFTA | R17: Arabic / English | Y17: =IF($C17="Africa","Manan",IF(OR($C17="Europe",$C17="South America",$C17="Oceania"),"Dev","Aditya")) -> Manan | AB17: =IF($M17="High",5,IF($M17="Medium",3,IF($M17="Home",4,IF($M17="Low",1,0)))) -> 4 | AD17: =IF(COUNT(Z17,AA17,AC17)=0,"",ROUND(Z17*'Scoring Guide'!$B$5+AA17*'Scoring Guide'!$B$6+AB17*'Scoring Guide'!$B$7+AC17*'Scoring Guide'!$B$8,2)) | AE17: =IF(AD17="","Not scored",IF(AD17>='Scoring Guide'!$B$11,"Tier 1 - Priority",IF(AD17>='Scoring Guide'!$B$12,"Tier 2 - Develop",IF(AD17>='Scoring Guide'!$B$13,"Tier 3 - Monitor","Tier 4 - Deprioritise")))) -> Not scored
A18: 10 | B18: Chad | C18: Africa | D18: Middle Africa | E18: 20300000 | F18: =IF($E18="","",IF($E18>=100000000,"Over 100 m",IF($E18>=25000000,"25-100 m",IF($E18>=5000000,"5-25 m",IF($E18>=1000000,"1-5 m","Under 1 m"))))) -> 5-25 m | G18: 13400000000 | H18: =IF(OR($G18="",$E18="",$E18=0),"",ROUND($G18/$E18,0)) -> 660 | I18: =IF($H18="","",IF($H18>14005,"High income",IF($H18>4515,"Upper-middle",IF($H18>1145,"Lower-middle","Low income")))) -> Low income | J18: Home | K18: Source continent | L18: Home market - not diaspora; served directly by SACVIN Nigeria / AfCFTA | M18: Home | N18: Yes | O18: Non-member | P18: Signatory | Q18: AfCFTA | R18: French | Y18: =IF($C18="Africa","Manan",IF(OR($C18="Europe",$C18="South America",$C18="Oceania"),"Dev","Aditya")) -> Manan | AB18: =IF($M18="High",5,IF($M18="Medium",3,IF($M18="Home",4,IF($M18="Low",1,0)))) -> 4 | AD18: =IF(COUNT(Z18,AA18,AC18)=0,"",ROUND(Z18*'Scoring Guide'!$B$5+AA18*'Scoring Guide'!$B$6+AB18*'Scoring Guide'!$B$7+AC18*'Scoring Guide'!$B$8,2)) | AE18: =IF(AD18="","Not scored",IF(AD18>='Scoring Guide'!$B$11,"Tier 1 - Priority",IF(AD18>='Scoring Guide'!$B$12,"Tier 2 - Develop",IF(AD18>='Scoring Guide'!$B$13,"Tier 3 - Monitor","Tier 4 - Deprioritise")))) -> Not scored
A19: 40 | B19: Rwanda | C19: Africa | D19: Eastern Africa | E19: 14500000 | F19: =IF($E19="","",IF($E19>=100000000,"Over 100 m",IF($E19>=25000000,"25-100 m",IF($E19>=5000000,"5-25 m",IF($E19>=1000000,"1-5 m","Under 1 m"))))) -> 5-25 m | G19: 14100000000 | H19: =IF(OR($G19="",$E19="",$E19=0),"",ROUND($G19/$E19,0)) -> 972 | I19: =IF($H19="","",IF($H19>14005,"High income",IF($H19>4515,"Upper-middle",IF($H19>1145,"Lower-middle","Low income")))) -> Low income | J19: Home | K19: Source continent | L19: Home market - not diaspora; served directly by SACVIN Nigeria / AfCFTA | M19: Home | N19: Yes | O19: Non-member | P19: Signatory | Q19: AfCFTA | R19: English | Y19: =IF($C19="Africa","Manan",IF(OR($C19="Europe",$C19="South America",$C19="Oceania"),"Dev","Aditya")) -> Manan | AB19: =IF($M19="High",5,IF($M19="Medium",3,IF($M19="Home",4,IF($M19="Low",1,0)))) -> 4 | AD19: =IF(COUNT(Z19,AA19,AC19)=0,"",ROUND(Z19*'Scoring Guide'!$B$5+AA19*'Scoring Guide'!$B$6+AB19*'Scoring Guide'!$B$7+AC19*'Scoring Guide'!$B$8,2)) | AE19: =IF(AD19="","Not scored",IF(AD19>='Scoring Guide'!$B$11,"Tier 1 - Priority",IF(AD19>='Scoring Guide'!$B$12,"Tier 2 - Develop",IF(AD19>='Scoring Guide'!$B$13,"Tier 3 - Monitor","Tier 4 - Deprioritise")))) -> Not scored
A20: 13 | B20: Congo (Republic of the) | C20: Africa | D20: Middle Africa | E20: 6400000 | F20: =IF($E20="","",IF($E20>=100000000,"Over 100 m",IF($E20>=25000000,"25-100 m",IF($E20>=5000000,"5-25 m",IF($E20>=1000000,"1-5 m","Under 1 m"))))) -> 5-25 m | G20: 15500000000 | H20: =IF(OR($G20="",$E20="",$E20=0),"",ROUND($G20/$E20,0)) -> 2422 | I20: =IF($H20="","",IF($H20>14005,"High income",IF($H20>4515,"Upper-middle",IF($H20>1145,"Lower-middle","Low income")))) -> Lower-middle | J20: Home | K20: Source continent | L20: Home market - not diaspora; served directly by SACVIN Nigeria / AfCFTA | M20: Home | N20: No | O20: Non-member | P20: Signatory | Q20: AfCFTA | R20: French | Y20: =IF($C20="Africa","Manan",IF(OR($C20="Europe",$C20="South America",$C20="Oceania"),"Dev","Aditya")) -> Manan | AB20: =IF($M20="High",5,IF($M20="Medium",3,IF($M20="Home",4,IF($M20="Low",1,0)))) -> 4 | AD20: =IF(COUNT(Z20,AA20,AC20)=0,"",ROUND(Z20*'Scoring Guide'!$B$5+AA20*'Scoring Guide'!$B$6+AB20*'Scoring Guide'!$B$7+AC20*'Scoring Guide'!$B$8,2)) | AE20: =IF(AD20="","Not scored",IF(AD20>='Scoring Guide'!$B$11,"Tier 1 - Priority",IF(AD20>='Scoring Guide'!$B$12,"Tier 2 - Develop",IF(AD20>='Scoring Guide'!$B$13,"Tier 3 - Monitor","Tier 4 - Deprioritise")))) -> Not scored
... A56: 55 | B56: Afghanistan | C56: Asia | D56: Southern Asia | E56: 43800000 | F56: =IF($E56="","",IF($E56>=100000000,"Over 100 m",IF($E56>=25000000,"25-100 m",IF($E56>=5000000,"5-25 m",IF($E56>=1000000,"1-5 m","Under 1 m"))))) -> 25-100 m | G56: 17200000000 | H56: =IF(OR($G56="",$E56="",$E56=0),"",ROUND($G56/$E56,0)) -> 393 | I56: =IF($H56="","",IF($H56>14005,"High income",IF($H56>4515,"Upper-middle",IF($H56>1145,"Lower-middle","Low income")))) -> Low income | J56: No | K56: Negligible | L56: No significant African-descent population | M56: Low | N56: Yes | O56: Not applicable | P56: Not applicable | Q56: SAARC | R56: Persian | Y56: =IF($C56="Africa","Manan",IF(OR($C56="Europe",$C56="South America",$C56="Oceania"),"Dev","Aditya")) -> Aditya | AB56: =IF($M56="High",5,IF($M56="Medium",3,IF($M56="Home",4,IF($M56="Low",1,0)))) -> 1 | AD56: =IF(COUNT(Z56,AA56,AC56)=0,"",ROUND(Z56*'Scoring Guide'!$B$5+AA56*'Scoring Guide'!$B$6+AB56*'Scoring Guide'!$B$7+AC56*'Scoring Guide'!$B$8,2)) | AE56: =IF(AD56="","Not scored",IF(AD56>='Scoring Guide'!$B$11,"Tier 1 - Priority",IF(AD56>='Scoring Guide'!$B$12,"Tier 2 - Develop",IF(AD56>='Scoring Guide'!$B$13,"Tier 3 - Monitor","Tier 4 - Deprioritise")))) -> Not scored
A57: 56 | B57: Armenia | C57: Asia | D57: Western Asia / Middle East | E57: 3000000 | F57: =IF($E57="","",IF($E57>=100000000,"Over 100 m",IF($E57>=25000000,"25-100 m",IF($E57>=5000000,"5-25 m",IF($E57>=1000000,"1-5 m","Under 1 m"))))) -> 1-5 m | G57: 25400000000 | H57: =IF(OR($G57="",$E57="",$E57=0),"",ROUND($G57/$E57,0)) -> 8467 | I57: =IF($H57="","",IF($H57>14005,"High income",IF($H57>4515,"Upper-middle",IF($H57>1145,"Lower-middle","Low income")))) -> Upper-middle | J57: No | K57: Negligible | L57: No significant African-descent population | M57: Low | N57: Yes | O57: Not applicable | P57: Not applicable | Q57: EAEU | R57: Russian | S57: Geographically in Asia; politically often grouped with Europe | Y57: =IF($C57="Africa","Manan",IF(OR($C57="Europe",$C57="South America",$C57="Oceania"),"Dev","Aditya")) -> Aditya | AB57: =IF($M57="High",5,IF($M57="Medium",3,IF($M57="Home",4,IF($M57="Low",1,0)))) -> 1 | AD57: =IF(COUNT(Z57,AA57,AC57)=0,"",ROUND(Z57*'Scoring Guide'!$B$5+AA57*'Scoring Guide'!$B$6+AB57*'Scoring Guide'!$B$7+AC57*'Scoring Guide'!$B$8,2)) | AE57: =IF(AD57="","Not scored",IF(AD57>='Scoring Guide'!$B$11,"Tier 1 - Priority",IF(AD57>='Scoring Guide'!$B$12,"Tier 2 - Develop",IF(AD57>='Scoring Guide'!$B$13,"Tier 3 - Monitor","Tier 4 - Deprioritise")))) -> Not scored
A58: 57 | B58: Azerbaijan | C58: Asia | D58: Western Asia / Middle East | E58: 10400000 | F58: =IF($E58="","",IF($E58>=100000000,"Over 100 m",IF($E58>=25000000,"25-100 m",IF($E58>=5000000,"5-25 m",IF($E58>=1000000,"1-5 m","Under 1 m"))))) -> 5-25 m | G58: 75600000000 | H58: =IF(OR($G58="",$E58="",$E58=0),"",ROUND($G58/$E58,0)) -> 7269 | I58: =IF($H58="","",IF($H58>14005,"High income",IF($H58>4515,"Upper-middle",IF($H58>1145,"Lower-middle","Low income")))) -> Upper-middle | J58: No | K58: Negligible | L58: No significant African-descent population | M58: Low | N58: Yes | O58: Not applicable | P58: Not applicable | Q58: No major bloc / MFN | R58: Russian | S58: Transcontinental - sometimes grouped with Europe | Y58: =IF($C58="Africa","Manan",IF(OR($C58="Europe",$C58="South America",$C58="Oceania"),"Dev","Aditya")) -> Aditya | AB58: =IF($M58="High",5,IF($M58="Medium",3,IF($M58="Home",4,IF($M58="Low",1,0)))) -> 1 | AD58: =IF(COUNT(Z58,AA58,AC58)=0,"",ROUND(Z58*'Scoring Guide'!$B$5+AA58*'Scoring Guide'!$B$6+AB58*'Scoring Guide'!$B$7+AC58*'Scoring Guide'!$B$8,2)) | AE58: =IF(AD58="","Not scored",IF(AD58>='Scoring Guide'!$B$11,"Tier 1 - Priority",IF(AD58>='Scoring Guide'!$B$12,"Tier 2 - Develop",IF(AD58>='Scoring Guide'!$B$13,"Tier 3 - Monitor","Tier 4 - Deprioritise")))) -> Not scored
A59: 58 | B59: Bahrain | C59: Asia | D59: Western Asia / Middle East | E59: 1650000 | F59: =IF($E59="","",IF($E59>=100000000,"Over 100 m",IF($E59>=25000000,"25-100 m",IF($E59>=5000000,"5-25 m",IF($E59>=1000000,"1-5 m","Under 1 m"))))) -> 1-5 m | G59: 47800000000 | H59: =IF(OR($G59="",$E59="",$E59=0),"",ROUND($G59/$E59,0)) -> 28970 | I59: =IF($H59="","",IF($H59>14005,"High income",IF($H59>4515,"Upper-middle",IF($H59>1145,"Lower-middle","Low income")))) -> High income | J59: Yes | K59: ~50,000 | L59: Historic Afro-Arab plus labour migration | M59: Low | N59: No | O59: Not applicable | P59: Not applicable | Q59: GCC Customs Union | R59: Arabic / English | Y59: =IF($C59="Africa","Manan",IF(OR($C59="Europe",$C59="South America",$C59="Oceania"),"Dev","Aditya")) -> Aditya | AB59: =IF($M59="High",5,IF($M59="Medium",3,IF($M59="Home",4,IF($M59="Low",1,0)))) -> 1 | AD59: =IF(COUNT(Z59,AA59,AC59)=0,"",ROUND(Z59*'Scoring Guide'!$B$5+AA59*'Scoring Guide'!$B$6+AB59*'Scoring Guide'!$B$7+AC59*'Scoring Guide'!$B$8,2)) | AE59: =IF(AD59="","Not scored",IF(AD59>='Scoring Guide'!$B$11,"Tier 1 - Priority",IF(AD59>='Scoring Guide'!$B$12,"Tier 2 - Develop",IF(AD59>='Scoring Guide'!$B$13,"Tier 3 - Monitor","Tier 4 - Deprioritise")))) -> Not scored
A60: 59 | B60: Bangladesh | C60: Asia | D60: Southern Asia | E60: 175700000 | F60: =IF($E60="","",IF($E60>=100000000,"Over 100 m",IF($E60>=25000000,"25-100 m",IF($E60>=5000000,"5-25 m",IF($E60>=1000000,"1-5 m","Under 1 m"))))) -> Over 100 m | G60: 451000000000 | H60: =IF(OR($G60="",$E60="",$E60=0),"",ROUND($G60/$E60,0)) -> 2567 | I60: =IF($H60="","",IF($H60>14005,"High income",IF($H60>4515,"Upper-middle",IF($H60>1145,"Lower-middle","Low income")))) -> Lower-middle | J60: No | K60: Negligible | L60: No significant African-descent population | M60: Low | N60: No | O60: Not applicable | P60: Not applicable | Q60: SAARC | R60: English | Y60: =IF($C60="Africa","Manan",IF(OR($C60="Europe",$C60="South America",$C60="Oceania"),"Dev","Aditya")) -> Aditya | AB60: =IF($M60="High",5,IF($M60="Medium",3,IF($M60="Home",4,IF($M60="Low",1,0)))) -> 1 | AD60: =IF(COUNT(Z60,AA60,AC60)=0,"",ROUND(Z60*'Scoring Guide'!$B$5+AA60*'Scoring Guide'!$B$6+AB60*'Scoring Guide'!$B$7+AC60*'Scoring Guide'!$B$8,2)) | AE60: =IF(AD60="","Not scored",IF(AD60>='Scoring Guide'!$B$11,"Tier 1 - Priority",IF(AD60>='Scoring Guide'!$B$12,"Tier 2 - Develop",IF(AD60>='Scoring Guide'!$B$13,"Tier 3 - Monitor","Tier 4 - Deprioritise")))) -> Not scored
A61: 60 | B61: Bhutan | C61: Asia | D61: Southern Asia | E61: 800000 | F61: =IF($E61="","",IF($E61>=100000000,"Over 100 m",IF($E61>=25000000,"25-100 m",IF($E61>=5000000,"5-25 m",IF($E61>=1000000,"1-5 m","Under 1 m"))))) -> Under 1 m | G61: 3100000000 | H61: =IF(OR($G61="",$E61="",$E61=0),"",ROUND($G61/$E61,0)) -> 3875 | I61: =IF($H61="","",IF($H61>14005,"High income",IF($H61>4515,"Upper-middle",IF($H61>1145,"Lower-middle","Low income")))) -> Lower-middle | J61: No | K61: Negligible | L61: No significant African-descent population | M61: Low | N61: Yes | O61: Not applicable | P61: Not applicable | Q61: SAARC | R61: English | Y61: =IF($C61="Africa","Manan",IF(OR($C61="Europe",$C61="South America",$C61="Oceania"),"Dev","Aditya")) -> Aditya | AB61: =IF($M61="High",5,IF($M61="Medium",3,IF($M61="Home",4,IF($M61="Low",1,0)))) -> 1 | AD61: =IF(COUNT(Z61,AA61,AC61)=0,"",ROUND(Z61*'Scoring Guide'!$B$5+AA61*'Scoring Guide'!$B$6+AB61*'Scoring Guide'!$B$7+AC61*'Scoring Guide'!$B$8,2)) | AE61: =IF(AD61="","Not scored",IF(AD61>='Scoring Guide'!$B$11,"Tier 1 - Priority",IF(AD61>='Scoring Guide'!$B$12,"Tier 2 - Develop",IF(AD61>='Scoring Guide'!$B$13,"Tier 3 - Monitor","Tier 4 - Deprioritise")))) -> Not scored
A62: 61 | B62: Brunei | C62: Asia | D62: South-Eastern Asia | E62: 460000 | F62: =IF($E62="","",IF($E62>=100000000,"Over 100 m",IF($E62>=25000000,"25-100 m",IF($E62>=5000000,"5-25 m",IF($E62>=1000000,"1-5 m","Under 1 m"))))) -> Under 1 m | G62: 15500000000 | H62: =IF(OR($G62="",$E62="",$E62=0),"",ROUND($G62/$E62,0)) -> 33696 | I62: =IF($H62="","",IF($H62>14005,"High income",IF($H62>4515,"Upper-middle",IF($H62>1145,"Lower-middle","Low income")))) -> High income | J62: No | K62: Negligible | L62: No significant African-descent population | M62: Low | N62: No | O62: Not applicable | P62: Not applicable | Q62: ASEAN | R62: Malay / English | Y62: =IF($C62="Africa","Manan",IF(OR($C62="Europe",$C62="South America",$C62="Oceania"),"Dev","Aditya")) -> Aditya | AB62: =IF($M62="High",5,IF($M62="Medium",3,IF($M62="Home",4,IF($M62="Low",1,0)))) -> 1 | AD62: =IF(COUNT(Z62,AA62,AC62)=0,"",ROUND(Z62*'Scoring Guide'!$B$5+AA62*'Scoring Guide'!$B$6+AB62*'Scoring Guide'!$B$7+AC62*'Scoring Guide'!$B$8,2)) | AE62: =IF(AD62="","Not scored",IF(AD62>='Scoring Guide'!$B$11,"Tier 1 - Priority",IF(AD62>='Scoring Guide'!$B$12,"Tier 2 - Develop",IF(AD62>='Scoring Guide'!$B$13,"Tier 3 - Monitor","Tier 4 - Deprioritise")))) -> Not scored
A63: 62 | B63: Cambodia | C63: Asia | D63: South-Eastern Asia | E63: 17800000 | F63: =IF($E63="","",IF($E63>=100000000,"Over 100 m",IF($E63>=25000000,"25-100 m",IF($E63>=5000000,"5-25 m",IF($E63>=1000000,"1-5 m","Under 1 m"))))) -> 5-25 m | G63: 47100000000 | H63: =IF(OR($G63="",$E63="",$E63=0),"",ROUND($G63/$E63,0)) -> 2646 | I63: =IF($H63="","",IF($H63>14005,"High income",IF($H63>4515,"Upper-middle",IF($H63>1145,"Lower-middle","Low income")))) -> Lower-middle | J63: No | K63: Negligible | L63: No significant African-descent population | M63: Low | N63: No | O63: Not applicable | P63: Not applicable | Q63: ASEAN | R63: English | Y63: =IF($C63="Africa","Manan",IF(OR($C63="Europe",$C63="South America",$C63="Oceania"),"Dev","Aditya")) -> Aditya | AB63: =IF($M63="High",5,IF($M63="Medium",3,IF($M63="Home",4,IF($M63="Low",1,0)))) -> 1 | AD63: =IF(COUNT(Z63,AA63,AC63)=0,"",ROUND(Z63*'Scoring Guide'!$B$5+AA63*'Scoring Guide'!$B$6+AB63*'Scoring Guide'!$B$7+AC63*'Scoring Guide'!$B$8,2)) | AE63: =IF(AD63="","Not scored",IF(AD63>='Scoring Guide'!$B$11,"Tier 1 - Priority",IF(AD63>='Scoring Guide'!$B$12,"Tier 2 - Develop",IF(AD63>='Scoring Guide'!$B$13,"Tier 3 - Monitor","Tier 4 - Deprioritise")))) -> Not scored
A64: 63 | B64: China | C64: Asia | D64: Eastern Asia | E64: 1416000000 | F64: =IF($E64="","",IF($E64>=100000000,"Over 100 m",IF($E64>=25000000,"25-100 m",IF($E64>=5000000,"5-25 m",IF($E64>=1000000,"1-5 m","Under 1 m"))))) -> Over 100 m | G64: 18750000000000 | H64: =IF(OR($G64="",$E64="",$E64=0),"",ROUND($G64/$E64,0)) -> 13242 | I64: =IF($H64="","",IF($H64>14005,"High income",IF($H64>4515,"Upper-middle",IF($H64>1145,"Lower-middle","Low income")))) -> Upper-middle | J64: Yes | K64: ~50,000 | L64: Guangzhou African trader hub - sourcing counterparty more than consumer market | M64: Medium | N64: No | O64: Not applicable | P64: Not applicable | Q64: No major bloc / MFN | R64: Mandarin / English | Y64: =IF($C64="Africa","Manan",IF(OR($C64="Europe",$C64="South America",$C64="Oceania"),"Dev","Aditya")) -> Aditya | AB64: =IF($M64="High",5,IF($M64="Medium",3,IF($M64="Home",4,IF($M64="Low",1,0)))) -> 3 | AD64: =IF(COUNT(Z64,AA64,AC64)=0,"",ROUND(Z64*'Scoring Guide'!$B$5+AA64*'Scoring Guide'!$B$6+AB64*'Scoring Guide'!$B$7+AC64*'Scoring Guide'!$B$8,2)) | AE64: =IF(AD64="","Not scored",IF(AD64>='Scoring Guide'!$B$11,"Tier 1 - Priority",IF(AD64>='Scoring Guide'!$B$12,"Tier 2 - Develop",IF(AD64>='Scoring Guide'!$B$13,"Tier 3 - Monitor","Tier 4 - Deprioritise")))) -> Not scored
A65: 64 | B65: Cyprus | C65: Asia | D65: Western Asia / Middle East | E65: 1370000 | F65: =IF($E65="","",IF($E65>=100000000,"Over 100 m",IF($E65>=25000000,"25-100 m",IF($E65>=5000000,"5-25 m",IF($E65>=1000000,"1-5 m","Under 1 m"))))) -> 1-5 m | G65: 34800000000 | H65: =IF(OR($G65="",$E65="",$E65=0),"",ROUND($G65/$E65,0)) -> 25401 | I65: =IF($H65="","",IF($H65>14005,"High income",IF($H65>4515,"Upper-middle",IF($H65>1145,"Lower-middle","Low income")))) -> High income | J65: No | K65: Negligible | L65: No significant African-descent population | M65: Low | N65: No | O65: Not applicable | P65: Not applicable | Q65: EU Single Market | R65: Greek | S65: Geographically in Asia; politically an EU member, often grouped with Europe | Y65: =IF($C65="Africa","Manan",IF(OR($C65="Europe",$C65="South America",$C65="Oceania"),"Dev","Aditya")) -> Aditya | AB65: =IF($M65="High",5,IF($M65="Medium",3,IF($M65="Home",4,IF($M65="Low",1,0)))) -> 1 | AD65: =IF(COUNT(Z65,AA65,AC65)=0,"",ROUND(Z65*'Scoring Guide'!$B$5+AA65*'Scoring Guide'!$B$6+AB65*'Scoring Guide'!$B$7+AC65*'Scoring Guide'!$B$8,2)) | AE65: =IF(AD65="","Not scored",IF(AD65>='Scoring Guide'!$B$11,"Tier 1 - Priority",IF(AD65>='Scoring Guide'!$B$12,"Tier 2 - Develop",IF(AD65>='Scoring Guide'!$B$13,"Tier 3 - Monitor","Tier 4 - Deprioritise")))) -> Not scored
A66: 65 | B66: Georgia | C66: Asia | D66: Western Asia / Middle East | E66: 3800000 | F66: =IF($E66="","",IF($E66>=100000000,"Over 100 m",IF($E66>=25000000,"25-100 m",IF($E66>=5000000,"5-25 m",IF($E66>=1000000,"1-5 m","Under 1 m"))))) -> 1-5 m | G66: 33000000000 | H66: =IF(OR($G66="",$E66="",$E66=0),"",ROUND($G66/$E66,0)) -> 8684 | I66: =IF($H66="","",IF($H66>14005,"High income",IF($H66>4515,"Upper-middle",IF($H66>1145,"Lower-middle","Low income")))) -> Upper-middle | J66: No | K66: Negligible | L66: No significant African-descent population | M66: Low | N66: No | O66: Not applicable | P66: Not applicable | Q66: No major bloc / MFN | R66: Russian | S66: Transcontinental - sometimes grouped with Europe | Y66: =IF($C66="Africa","Manan",IF(OR($C66="Europe",$C66="South America",$C66="Oceania"),"Dev","Aditya")) -> Aditya | AB66: =IF($M66="High",5,IF($M66="Medium",3,IF($M66="Home",4,IF($M66="Low",1,0)))) -> 1 | AD66: =IF(COUNT(Z66,AA66,AC66)=0,"",ROUND(Z66*'Scoring Guide'!$B$5+AA66*'Scoring Guide'!$B$6+AB66*'Scoring Guide'!$B$7+AC66*'Scoring Guide'!$B$8,2)) | AE66: =IF(AD66="","Not scored",IF(AD66>='Scoring Guide'!$B$11,"Tier 1 - Priority",IF(AD66>='Scoring Guide'!$B$12,"Tier 2 - Develop",IF(AD66>='Scoring Guide'!$B$13,"Tier 3 - Monitor","Tier 4 - Deprioritise")))) -> Not scored
A67: 66 | B67: India | C67: Asia | D67: Southern Asia | E67: 1463000000 | F67: =IF($E67="","",IF($E67>=100000000,"Over 100 m",IF($E67>=25000000,"25-100 m",IF($E67>=5000000,"5-25 m",IF($E67>=1000000,"1-5 m","Under 1 m"))))) -> Over 100 m | G67: 3910000000000 | H67: =IF(OR($G67="",$E67="",$E67=0),"",ROUND($G67/$E67,0)) -> 2673 | I67: =IF($H67="","",IF($H67>14005,"High income",IF($H67>4515,"Upper-middle",IF($H67>1145,"Lower-middle","Low income")))) -> Lower-middle | J67: Yes | K67: ~70,000 Siddi + students/traders | L67: Siddi community plus African students and traders | M67: Low | N67: No | O67: Not applicable | P67: Not applicable | Q67: SAARC | R67: English | Y67: =IF($C67="Africa","Manan",IF(OR($C67="Europe",$C67="South America",$C67="Oceania"),"Dev","Aditya")) -> Aditya | AB67: =IF($M67="High",5,IF($M67="Medium",3,IF($M67="Home",4,IF($M67="Low",1,0)))) -> 1 | AD67: =IF(COUNT(Z67,AA67,AC67)=0,"",ROUND(Z67*'Scoring Guide'!$B$5+AA67*'Scoring Guide'!$B$6+AB67*'Scoring Guide'!$B$7+AC67*'Scoring Guide'!$B$8,2)) | AE67: =IF(AD67="","Not scored",IF(AD67>='Scoring Guide'!$B$11,"Tier 1 - Priority",IF(AD67>='Scoring Guide'!$B$12,"Tier 2 - Develop",IF(AD67>='Scoring Guide'!$B$13,"Tier 3 - Monitor","Tier 4 - Deprioritise")))) -> Not scored
A68: 67 | B68: Indonesia | C68: Asia | D68: South-Eastern Asia | E68: 286000000 | F68: =IF($E68="","",IF($E68>=100000000,"Over 100 m",IF($E68>=25000000,"25-100 m",IF($E68>=5000000,"5-25 m",IF($E68>=1000000,"1-5 m","Under 1 m"))))) -> Over 100 m | G68: 1400000000000 | H68: =IF(OR($G68="",$E68="",$E68=0),"",ROUND($G68/$E68,0)) -> 4895 | I68: =IF($H68="","",IF($H68>14005,"High income",IF($H68>4515,"Upper-middle",IF($H68>1145,"Lower-middle","Low income")))) -> Upper-middle | J68: No | K68: Negligible | L68: No significant African-descent population | M68: Low | N68: No | O68: Not applicable | P68: Not applicable | Q68: ASEAN | R68: Bahasa Indonesia | Y68: =IF($C68="Africa","Manan",IF(OR($C68="Europe",$C68="South America",$C68="Oceania"),"Dev","Aditya")) -> Aditya | AB68: =IF($M68="High",5,IF($M68="Medium",3,IF($M68="Home",4,IF($M68="Low",1,0)))) -> 1 | AD68: =IF(COUNT(Z68,AA68,AC68)=0,"",ROUND(Z68*'Scoring Guide'!$B$5+AA68*'Scoring Guide'!$B$6+AB68*'Scoring Guide'!$B$7+AC68*'Scoring Guide'!$B$8,2)) | AE68: =IF(AD68="","Not scored",IF(AD68>='Scoring Guide'!$B$11,"Tier 1 - Priority",IF(AD68>='Scoring Guide'!$B$12,"Tier 2 - Develop",IF(AD68>='Scoring Guide'!$B$13,"Tier 3 - Monitor","Tier 4 - Deprioritise")))) -> Not scored
A69: 68 | B69: Iran | C69: Asia | D69: Southern Asia | E69: 92400000 | F69: =IF($E69="","",IF($E69>=100000000,"Over 100 m",IF($E69>=25000000,"25-100 m",IF($E69>=5000000,"5-25 m",IF($E69>=1000000,"1-5 m","Under 1 m"))))) -> 25-100 m | G69: 434000000000 | H69: =IF(OR($G69="",$E69="",$E69=0),"",ROUND($G69/$E69,0)) -> 4697 | I69: =IF($H69="","",IF($H69>14005,"High income",IF($H69>4515,"Upper-middle",IF($H69>1145,"Lower-middle","Low income")))) -> Upper-middle | J69: Yes | K69: ~0.1 m | L69: Afro-Iranian community (southern coast) | M69: Low | N69: No | O69: Not applicable | P69: Not applicable | Q69: No major bloc / MFN | R69: Persian | Y69: =IF($C69="Africa","Manan",IF(OR($C69="Europe",$C69="South America",$C69="Oceania"),"Dev","Aditya")) -> Aditya | AB69: =IF($M69="High",5,IF($M69="Medium",3,IF($M69="Home",4,IF($M69="Low",1,0)))) -> 1 | AD69: =IF(COUNT(Z69,AA69,AC69)=0,"",ROUND(Z69*'Scoring Guide'!$B$5+AA69*'Scoring Guide'!$B$6+AB69*'Scoring Guide'!$B$7+AC69*'Scoring Guide'!$B$8,2)) | AE69: =IF(AD69="","Not scored",IF(AD69>='Scoring Guide'!$B$11,"Tier 1 - Priority",IF(AD69>='Scoring Guide'!$B$12,"Tier 2 - Develop",IF(AD69>='Scoring Guide'!$B$13,"Tier 3 - Monitor","Tier 4 - Deprioritise")))) -> Not scored
A70: 69 | B70: Iraq | C70: Asia | D70: Western Asia / Middle East | E70: 47000000 | F70: =IF($E70="","",IF($E70>=100000000,"Over 100 m",IF($E70>=25000000,"25-100 m",IF($E70>=5000000,"5-25 m",IF($E70>=1000000,"1-5 m","Under 1 m"))))) -> 25-100 m | G70: 264000000000 | H70: =IF(OR($G70="",$E70="",$E70=0),"",ROUND($G70/$E70,0)) -> 5617 | I70: =IF($H70="","",IF($H70>14005,"High income",IF($H70>4515,"Upper-middle",IF($H70>1145,"Lower-middle","Low income")))) -> Upper-middle | J70: Yes | K70: ~0.25 m | L70: Afro-Iraqi community (Basra region) | M70: Low | N70: No | O70: Not applicable | P70: Not applicable | Q70: No major bloc / MFN | R70: Arabic / English | Y70: =IF($C70="Africa","Manan",IF(OR($C70="Europe",$C70="South America",$C70="Oceania"),"Dev","Aditya")) -> Aditya | AB70: =IF($M70="High",5,IF($M70="Medium",3,IF($M70="Home",4,IF($M70="Low",1,0)))) -> 1 | AD70: =IF(COUNT(Z70,AA70,AC70)=0,"",ROUND(Z70*'Scoring Guide'!$B$5+AA70*'Scoring Guide'!$B$6+AB70*'Scoring Guide'!$B$7+AC70*'Scoring Guide'!$B$8,2)) | AE70: =IF(AD70="","Not scored",IF(AD70>='Scoring Guide'!$B$11,"Tier 1 - Priority",IF(AD70>='Scoring Guide'!$B$12,"Tier 2 - Develop",IF(AD70>='Scoring Guide'!$B$13,"Tier 3 - Monitor","Tier 4 - Deprioritise")))) -> Not scored
A71: 70 | B71: Israel | C71: Asia | D71: Western Asia / Middle East | E71: 9800000 | F71: =IF($E71="","",IF($E71>=100000000,"Over 100 m",IF($E71>=25000000,"25-100 m",IF($E71>=5000000,"5-25 m",IF($E71>=1000000,"1-5 m","Under 1 m"))))) -> 5-25 m | G71: 530000000000 | H71: =IF(OR($G71="",$E71="",$E71=0),"",ROUND($G71/$E71,0)) -> 54082 | I71: =IF($H71="","",IF($H71>14005,"High income",IF($H71>4515,"Upper-middle",IF($H71>1145,"Lower-middle","Low income")))) -> High income | J71: Yes | K71: ~0.16 m | L71: Ethiopian-Israeli community plus asylum seekers | M71: Low | N71: No | O71: Not applicable | P71: Not applicable | Q71: No major bloc / MFN | R71: Hebrew / English | Y71: =IF($C71="Africa","Manan",IF(OR($C71="Europe",$C71="South America",$C71="Oceania"),"Dev","Aditya")) -> Aditya | AB71: =IF($M71="High",5,IF($M71="Medium",3,IF($M71="Home",4,IF($M71="Low",1,0)))) -> 1 | AD71: =IF(COUNT(Z71,AA71,AC71)=0,"",ROUND(Z71*'Scoring Guide'!$B$5+AA71*'Scoring Guide'!$B$6+AB71*'Scoring Guide'!$B$7+AC71*'Scoring Guide'!$B$8,2)) | AE71: =IF(AD71="","Not scored",IF(AD71>='Scoring Guide'!$B$11,"Tier 1 - Priority",IF(AD71>='Scoring Guide'!$B$12,"Tier 2 - Develop",IF(AD71>='Scoring Guide'!$B$13,"Tier 3 - Monitor","Tier 4 - Deprioritise")))) -> Not scored
A72: 71 | B72: Japan | C72: Asia | D72: Eastern Asia | E72: 123100000 | F72: =IF($E72="","",IF($E72>=100000000,"Over 100 m",IF($E72>=25000000,"25-100 m",IF($E72>=5000000,"5-25 m",IF($E72>=1000000,"1-5 m","Under 1 m"))))) -> Over 100 m | G72: 4070000000000 | H72: =IF(OR($G72="",$E72="",$E72=0),"",ROUND($G72/$E72,0)) -> 33063 | I72: =IF($H72="","",IF($H72>14005,"High income",IF($H72>4515,"Upper-middle",IF($H72>1145,"Lower-middle","Low income")))) -> High income | J72: Yes | K72: ~20,000 | L72: Small African community | M72: Low | N72: No | O72: Not applicable | P72: Not applicable | Q72: No major bloc / MFN | R72: Japanese | Y72: =IF($C72="Africa","Manan",IF(OR($C72="Europe",$C72="South America",$C72="Oceania"),"Dev","Aditya")) -> Aditya | AB72: =IF($M72="High",5,IF($M72="Medium",3,IF($M72="Home",4,IF($M72="Low",1,0)))) -> 1 | AD72: =IF(COUNT(Z72,AA72,AC72)=0,"",ROUND(Z72*'Scoring Guide'!$B$5+AA72*'Scoring Guide'!$B$6+AB72*'Scoring Guide'!$B$7+AC72*'Scoring Guide'!$B$8,2)) | AE72: =IF(AD72="","Not scored",IF(AD72>='Scoring Guide'!$B$11,"Tier 1 - Priority",IF(AD72>='Scoring Guide'!$B$12,"Tier 2 - Develop",IF(AD72>='Scoring Guide'!$B$13,"Tier 3 - Monitor","Tier 4 - Deprioritise")))) -> Not scored
A73: 72 | B73: Jordan | C73: Asia | D73: Western Asia / Middle East | E73: 11600000 | F73: =IF($E73="","",IF($E73>=100000000,"Over 100 m",IF($E73>=25000000,"25-100 m",IF($E73>=5000000,"5-25 m",IF($E73>=1000000,"1-5 m","Under 1 m"))))) -> 5-25 m | G73: 53300000000 | H73: =IF(OR($G73="",$E73="",$E73=0),"",ROUND($G73/$E73,0)) -> 4595 | I73: =IF($H73="","",IF($H73>14005,"High income",IF($H73>4515,"Upper-middle",IF($H73>1145,"Lower-middle","Low income")))) -> Upper-middle | J73: Yes | K73: ~50,000 | L73: African migrant workers | M73: Low | N73: No | O73: Not applicable | P73: Not applicable | Q73: No major bloc / MFN | R73: Arabic / English | Y73: =IF($C73="Africa","Manan",IF(OR($C73="Europe",$C73="South America",$C73="Oceania"),"Dev","Aditya")) -> Aditya | AB73: =IF($M73="High",5,IF($M73="Medium",3,IF($M73="Home",4,IF($M73="Low",1,0)))) -> 1 | AD73: =IF(COUNT(Z73,AA73,AC73)=0,"",ROUND(Z73*'Scoring Guide'!$B$5+AA73*'Scoring Guide'!$B$6+AB73*'Scoring Guide'!$B$7+AC73*'Scoring Guide'!$B$8,2)) | AE73: =IF(AD73="","Not scored",IF(AD73>='Scoring Guide'!$B$11,"Tier 1 - Priority",IF(AD73>='Scoring Guide'!$B$12,"Tier 2 - Develop",IF(AD73>='Scoring Guide'!$B$13,"Tier 3 - Monitor","Tier 4 - Deprioritise")))) -> Not scored
A74: 73 | B74: Kazakhstan | C74: Asia | D74: Central Asia | E74: 20600000 | F74: =IF($E74="","",IF($E74>=100000000,"Over 100 m",IF($E74>=25000000,"25-100 m",IF($E74>=5000000,"5-25 m",IF($E74>=1000000,"1-5 m","Under 1 m"))))) -> 5-25 m | G74: 292000000000 | H74: =IF(OR($G74="",$E74="",$E74=0),"",ROUND($G74/$E74,0)) -> 14175 | I74: =IF($H74="","",IF($H74>14005,"High income",IF($H74>4515,"Upper-middle",IF($H74>1145,"Lower-middle","Low income")))) -> High income | J74: No | K74: Negligible | L74: No significant African-descent population | M74: Low | N74: Yes | O74: Not applicable | P74: Not applicable | Q74: EAEU | R74: Russian | S74: Transcontinental - western portion lies in Europe | Y74: =IF($C74="Africa","Manan",IF(OR($C74="Europe",$C74="South America",$C74="Oceania"),"Dev","Aditya")) -> Aditya | AB74: =IF($M74="High",5,IF($M74="Medium",3,IF($M74="Home",4,IF($M74="Low",1,0)))) -> 1 | AD74: =IF(COUNT(Z74,AA74,AC74)=0,"",ROUND(Z74*'Scoring Guide'!$B$5+AA74*'Scoring Guide'!$B$6+AB74*'Scoring Guide'!$B$7+AC74*'Scoring Guide'!$B$8,2)) | AE74: =IF(AD74="","Not scored",IF(AD74>='Scoring Guide'!$B$11,"Tier 1 - Priority",IF(AD74>='Scoring Guide'!$B$12,"Tier 2 - Develop",IF(AD74>='Scoring Guide'!$B$13,"Tier 3 - Monitor","Tier 4 - Deprioritise")))) -> Not scored
A75: 74 | B75: Kuwait | C75: Asia | D75: Western Asia / Middle East | E75: 5000000 | F75: =IF($E75="","",IF($E75>=100000000,"Over 100 m",IF($E75>=25000000,"25-100 m",IF($E75>=5000000,"5-25 m",IF($E75>=1000000,"1-5 m","Under 1 m"))))) -> 5-25 m | G75: 162000000000 | H75: =IF(OR($G75="",$E75="",$E75=0),"",ROUND($G75/$E75,0)) -> 32400 | I75: =IF($H75="","",IF($H75>14005,"High income",IF($H75>4515,"Upper-middle",IF($H75>1145,"Lower-middle","Low income")))) -> High income | J75: Yes | K75: ~0.1 m | L75: African labour migration | M75: Low | N75: No | O75: Not applicable | P75: Not applicable | Q75: GCC Customs Union | R75: Arabic / English | Y75: =IF($C75="Africa","Manan",IF(OR($C75="Europe",$C75="South America",$C75="Oceania"),"Dev","Aditya")) -> Aditya | AB75: =IF($M75="High",5,IF($M75="Medium",3,IF($M75="Home",4,IF($M75="Low",1,0)))) -> 1 | AD75: =IF(COUNT(Z75,AA75,AC75)=0,"",ROUND(Z75*'Scoring Guide'!$B$5+AA75*'Scoring Guide'!$B$6+AB75*'Scoring Guide'!$B$7+AC75*'Scoring Guide'!$B$8,2)) | AE75: =IF(AD75="","Not scored",IF(AD75>='Scoring Guide'!$B$11,"Tier 1 - Priority",IF(AD75>='Scoring Guide'!$B$12,"Tier 2 - Develop",IF(AD75>='Scoring Guide'!$B$13,"Tier 3 - Monitor","Tier 4 - Deprioritise")))) -> Not scored
...

Sheet Scoring Guide
A1: Export Targeting - Scoring Model
A3: Weights (must total 100%) - edit the yellow cells to re-weight the model
A4: Criterion | B4: Weight
A5: Market Size | B5: 0.3
A6: Access Ease | B6: 0.25
A7: Diaspora Fit | B7: 0.2
A8: Competition | B8: 0.25
A9: Total | B9: =SUM(B5:B8) -> 1
A10: Tier cut-offs (weighted score)
A11: Tier 1 - Priority | B11: 4
A12: Tier 2 - Develop | B12: 3
A13: Tier 3 - Monitor | B13: 2
A16: HOW TO USE
A17: 1. Fill the amber columns (T-Y) on the main sheet from your own sources.
A18: 2. Enter 1-5 scores in columns Z, AA and AC. Column AB (Diaspora Fit) is already auto-filled from the Diaspora Priority column.
A19: 3. Weighted Score (AD) and Priority Tier (AE) calculate automatically.
A20: 4. Filter column AE to Tier 1 to get the target list.
A22: SCORING SCALES (1 = worst, 5 = best)
A23: Market Size | B23: 5 = large population with high plasticware import volume; 1 = tiny or negligible import demand
A24: Access Ease | B24: 5 = duty-free (ECOWAS/AfCFTA), coastal, short transit, no NTBs; 1 = high duty, landlocked, licensing barriers, FX restrictions
A25: Diaspora Fit | B25: Auto: High=5, Home=4, Medium=3, Low=1. Override manually if you have better local intelligence.
A26: Competition | B26: 5 = little local manufacturing, imports dominate; 1 = strong domestic plastics industry plus entrenched Chinese/Turkish supply
A28: WORKED EXAMPLE (do not enter this as a row - it shows the expected format)
A29: Country | B29: United Kingdom
A30: Existing Buyer? (Y/N) | B30: Y
A31: Import Duty % (HS 3923/3924) | B31: 6.5%
A32: Est. Annual Import Value (USD) | B32: 1,200,000
A33: Local Competition (H/M/L) | B33: M
A34: Distributor Status | B34: Appointed - London
A35: Owner | B35: Shafeeq
A36: Market Size / Access Ease / Competition | B36: 4 / 4 / 3
A37: Resulting Weighted Score | B37: 3.80 -> Tier 2 - Develop
A39: DATA SOURCES AND CAVEATS
A40: GDP is nominal (not PPP) in current USD, full-year 2024, on the basis of IMF World Economic Outlook estimates, rounded to 3 significant figures. Nominal is the right basis for export pricing because you invoice in hard currency. GDP per Capita (column H) and Income Tier (column I) are formulas derived from columns G and E, so they update if you overwrite either. Income Tier applies World Bank thresholds (High >14,005; Upper-middle 4,516-14,005; Lower-middle 1,146-4,515; Low <1,146) - note those thresholds are set against GNI per capita, so using GDP per capita as the input makes the tier indicative rather than official. Vatican City publishes no GDP and is left blank. Cuba, Syria, North Korea, Venezuela and Eritrea figures are weak - treat them as placeholders.
A41: Population figures are rounded 2025 estimates on the basis of the UN World Population Prospects. They are stated to 2-3 significant figures and are intended for banding and rough market sizing, not for reporting. Refresh from the UN WPP or World Bank WDI before using them in any external document. Population Band (column F) is a formula and re-derives automatically if you overwrite a population figure.
A42: Diaspora figures are indicative mid-range estimates compiled from UN migration stock data, national census records and Wikipedia country articles. Definitions of 'African descent' vary widely between countries (Brazil ranges from 20 m to 112 m depending on the definition used), so treat these as orders of magnitude, not audited figures.
A43: Diaspora Priority separates two very different commercial situations: countries where an African MIGRANT community sustains a specialist import and ethnic-retail channel (High), and countries with a large Afro-descendant population that is simply the general market and buys through ordinary retail (Medium/Low).
A44: ECOWAS: Burkina Faso, Mali and Niger formally exited on 29 January 2025 and formed the Alliance of Sahel States. ECOWAS has provisionally continued ETLS trade treatment for their goods until full modalities are agreed - verify current status before pricing.
A45: AfCFTA: 'Signatory' covers all African Union members except Eritrea. Signature is not the same as ratification or active tariff-schedule implementation - confirm per corridor before relying on preferential duty.
A46: Import duty, import value and competition columns are deliberately left blank. Populate them from your GlobalWits trade data and the national tariff schedules rather than from estimates.

Sheet Summary
A1: Countries by Continent - Summary
A3: Continent | B3: Countries | C3: % of Total | D3: Population (2025 est.) | E3: % of World Pop. | F3: GDP Nominal USD (2024) | G3: % of World GDP | H3: GDP per Capita, USD | I3: Diaspora = Yes | J3: High Priority | K3: Medium Priority
A4: Africa | B4: =COUNTIF('Countries by Continent'!$C$2:$C$196,$A4) -> 54 | C4: =IFERROR(B4/$B$10,0) -> 0.27692308 | D4: =SUMIF('Countries by Continent'!$C$2:$C$196,$A4,'Countries by Continent'!$E$2:$E$196) -> 1541850000 | E4: =IFERROR(D4/$D$10,0) -> 0.18842257 | F4: =SUMIF('Countries by Continent'!$C$2:$C$196,$A4,'Countries by Continent'!$G$2:$G$196) -> 2795050000000 | G4: =IFERROR(F4/$F$10,0) -> 0.025562432 | H4: =IFERROR(ROUND(F4/D4,0),0) -> 1813 | I4: =COUNTIFS('Countries by Continent'!$C$2:$C$196,$A4,'Countries by Continent'!$J$2:$J$196,"Yes") -> 0 | J4: =COUNTIFS('Countries by Continent'!$C$2:$C$196,$A4,'Countries by Continent'!$M$2:$M$196,"High") -> 0 | K4: =COUNTIFS('Countries by Continent'!$C$2:$C$196,$A4,'Countries by Continent'!$M$2:$M$196,"Medium") -> 0
A5: Asia | B5: =COUNTIF('Countries by Continent'!$C$2:$C$196,$A5) -> 48 | C5: =IFERROR(B5/$B$10,0) -> 0.24615385 | D5: =SUMIF('Countries by Continent'!$C$2:$C$196,$A5,'Countries by Continent'!$E$2:$E$196) -> 4803760000 | E5: =IFERROR(D5/$D$10,0) -> 0.58704596 | F5: =SUMIF('Countries by Continent'!$C$2:$C$196,$A5,'Countries by Continent'!$G$2:$G$196) -> 39197400000000 | G5: =IFERROR(F5/$F$10,0) -> 0.35848406 | H5: =IFERROR(ROUND(F5/D5,0),0) -> 8160 | I5: =COUNTIFS('Countries by Continent'!$C$2:$C$196,$A5,'Countries by Continent'!$J$2:$J$196,"Yes") -> 19 | J5: =COUNTIFS('Countries by Continent'!$C$2:$C$196,$A5,'Countries by Continent'!$M$2:$M$196,"High") -> 1 | K5: =COUNTIFS('Countries by Continent'!$C$2:$C$196,$A5,'Countries by Continent'!$M$2:$M$196,"Medium") -> 5
A6: Europe | B6: =COUNTIF('Countries by Continent'!$C$2:$C$196,$A6) -> 44 | C6: =IFERROR(B6/$B$10,0) -> 0.22564103 | D6: =SUMIF('Countries by Continent'!$C$2:$C$196,$A6,'Countries by Continent'!$E$2:$E$196) -> 741095800 | E6: =IFERROR(D6/$D$10,0) -> 0.090565993 | F6: =SUMIF('Countries by Continent'!$C$2:$C$196,$A6,'Countries by Continent'!$G$2:$G$196) -> 27006200000000 | G6: =IFERROR(F6/$F$10,0) -> 0.24698812 | H6: =IFERROR(ROUND(F6/D6,0),0) -> 36441 | I6: =COUNTIFS('Countries by Continent'!$C$2:$C$196,$A6,'Countries by Continent'!$J$2:$J$196,"Yes") -> 19 | J6: =COUNTIFS('Countries by Continent'!$C$2:$C$196,$A6,'Countries by Continent'!$M$2:$M$196,"High") -> 7 | K6: =COUNTIFS('Countries by Continent'!$C$2:$C$196,$A6,'Countries by Continent'!$M$2:$M$196,"Medium") -> 5
A7: North America | B7: =COUNTIF('Countries by Continent'!$C$2:$C$196,$A7) -> 23 | C7: =IFERROR(B7/$B$10,0) -> 0.11794872 | D7: =SUMIF('Countries by Continent'!$C$2:$C$196,$A7,'Countries by Continent'!$E$2:$E$196) -> 612297000 | E7: =IFERROR(D7/$D$10,0) -> 0.07482607 | F7: =SUMIF('Countries by Continent'!$C$2:$C$196,$A7,'Countries by Continent'!$G$2:$G$196) -> 33964400000000 | G7: =IFERROR(F7/$F$10,0) -> 0.31062509 | H7: =IFERROR(ROUND(F7/D7,0),0) -> 55470 | I7: =COUNTIFS('Countries by Continent'!$C$2:$C$196,$A7,'Countries by Continent'!$J$2:$J$196,"Yes") -> 23 | J7: =COUNTIFS('Countries by Continent'!$C$2:$C$196,$A7,'Countries by Continent'!$M$2:$M$196,"High") -> 2 | K7: =COUNTIFS('Countries by Continent'!$C$2:$C$196,$A7,'Countries by Continent'!$M$2:$M$196,"Medium") -> 6
A8: South America | B8: =COUNTIF('Countries by Continent'!$C$2:$C$196,$A8) -> 12 | C8: =IFERROR(B8/$B$10,0) -> 0.061538462 | D8: =SUMIF('Countries by Continent'!$C$2:$C$196,$A8,'Countries by Continent'!$E$2:$E$196) -> 437980000 | E8: =IFERROR(D8/$D$10,0) -> 0.053523571 | F8: =SUMIF('Countries by Continent'!$C$2:$C$196,$A8,'Countries by Continent'!$G$2:$G$196) -> 4280400000000 | G8: =IFERROR(F8/$F$10,0) -> 0.039146861 | H8: =IFERROR(ROUND(F8/D8,0),0) -> 9773 | I8: =COUNTIFS('Countries by Continent'!$C$2:$C$196,$A8,'Countries by Continent'!$J$2:$J$196,"Yes") -> 12 | J8: =COUNTIFS('Countries by Continent'!$C$2:$C$196,$A8,'Countries by Continent'!$M$2:$M$196,"High") -> 0 | K8: =COUNTIFS('Countries by Continent'!$C$2:$C$196,$A8,'Countries by Continent'!$M$2:$M$196,"Medium") -> 5
A9: Oceania | B9: =COUNTIF('Countries by Continent'!$C$2:$C$196,$A9) -> 14 | C9: =IFERROR(B9/$B$10,0) -> 0.071794872 | D9: =SUMIF('Countries by Continent'!$C$2:$C$196,$A9,'Countries by Continent'!$E$2:$E$196) -> 45954000 | E9: =IFERROR(D9/$D$10,0) -> 0.0056158322 | F9: =SUMIF('Countries by Continent'!$C$2:$C$196,$A9,'Countries by Continent'!$G$2:$G$196) -> 2098650000000 | G9: =IFERROR(F9/$F$10,0) -> 0.019193431 | H9: =IFERROR(ROUND(F9/D9,0),0) -> 45668 | I9: =COUNTIFS('Countries by Continent'!$C$2:$C$196,$A9,'Countries by Continent'!$J$2:$J$196,"Yes") -> 2 | J9: =COUNTIFS('Countries by Continent'!$C$2:$C$196,$A9,'Countries by Continent'!$M$2:$M$196,"High") -> 0 | K9: =COUNTIFS('Countries by Continent'!$C$2:$C$196,$A9,'Countries by Continent'!$M$2:$M$196,"Medium") -> 1
A10: Total | B10: =SUM(B4:B9) -> 195 | C10: =SUM(C4:C9) -> 1 | D10: =SUM(D4:D9) -> 8182936800 | E10: =SUM(E4:E9) -> 1 | F10: =SUM(F4:F9) -> 109342100000000 | G10: =SUM(G4:G9) -> 1 | H10: =IFERROR(ROUND(F10/D10,0),0) -> 13362 | I10: =SUM(I4:I9) -> 75 | J10: =SUM(J4:J9) -> 10 | K10: =SUM(K4:K9) -> 22
A12: Scope
A13: Antarctica excluded as requested - it has no countries, only Antarctic Treaty research stations.
A14: 195 states: the 193 UN members plus Vatican City and Palestine (UN permanent observer states).
A15: Not included: Taiwan, Kosovo, Western Sahara, Northern Cyprus, Hong Kong, Macau, Puerto Rico, Greenland and other dependent or partially recognised territories.
A16: 'Diaspora = Yes' counts countries outside Africa with a commercially meaningful African-descent population. African countries are marked 'Home' and are excluded from that count.
A17: See the Scoring Guide tab for definitions, caveats and how to use the amber input columns.
