Workbook

Sheet READ ME
B2: SACVIN | EXPORT LEAD ENRICHMENT
B3: Find the right buyers, know more about them than the competition does, and contact the best ones first.
B5: THE SHEETS
B6: LEAD MASTER | C6: One row per company, 57 fields in seven groups. Type in the coloured columns; the grey ones calculate themselves. Rows 3-5 are worked examples — read them, then delete and enter your own.
B7: CONTACTS | C7: One row per person, for companies with more than one buyer worth knowing. Enter the Lead ID and the company name fills in.
B8: ENRICHMENT GUIDE | C8: Every field explained: what it means, where to get it, whether it is mandatory, and a worked example. This is the sheet you hand to whoever does the research.
B9: SCORING | C9: The fit-score model. Six components, 100 points. Change the yellow numbers and every lead re-scores.
B10: SUMMARY | C10: Counts by tier, business type and region, plus data quality. Open it to see whether the list is getting better or just longer.
B11: LISTS | C11: All dropdowns and a 130-country to region reference table. Edit the dropdowns to match how your team actually works.
B13: THE SEVEN FIELD GROUPS ON LEAD MASTER
B14: 1 · Record | C14: Lead ID, when it was added, by whom, and where it is in the enrichment process.
B15: 2 · Company | C15: Who they are — name, website, country, business type, categories, size, revenue. Region fills in automatically from the country.
B16: 3 · Import intelligence | C16: The part that separates a list from a target list: do they import, what HS codes, from which countries, from which suppliers, how much and how often. This is what tells you whom you are displacing.
B17: 4 · Commercial fit | C17: Discharge port, duty and preference position, compliance requirements, language, and which SACVIN products to lead with.
B18: 5 · Primary contact | C18: The buying decision maker — name, title, role, verified email, phone, LinkedIn.
B19: 6 · Source & data quality | C19: Which tool the record came from, when it was pulled, who verified it, how complete it is, and whether it is a duplicate.
B20: 7 · Scoring | C20: Fit score out of 100 and an A/B/C/D tier. Calculated — never typed.
B22: HOW THE SCORE WORKS
B23: 100 points, six parts | C23: Business type 25 · Already importing 20 · Sourcing from a competing origin 20 · Company size 15 · Category match 10 · Contact quality 10.
B24: Tiers | C24: A is 75 and above — contact first. B is 60-74. C is 40-59 — worth enriching further. D is below 40 — park or disqualify.
B25: Change it freely | C25: The weights are yellow cells on the SCORING sheet. If your first fifty conversations say retail chains convert better than distributors, change the number rather than argue about it.
B26: A caution | C26: A score sorts a list; it does not qualify a buyer. A C-tier lead with the right person on the phone beats an A-tier lead nobody has called.
B28: THE WORKING METHOD
B29: Step 1 · Build the list | C29: Apify or a trade directory for plastic houseware distributors, wholesalers, importers and retail chains in the target country. Fill group 2. Aim for breadth here, not depth.
B30: Step 2 · Find the buyer | C30: LinkedIn Sales Navigator for purchasing, procurement, category buyer and import manager titles at those companies. Fill group 5.
B31: Step 3 · Get contact details | C31: Apollo for verified email and phone. Record the email status honestly — sending to invalid addresses damages your sending domain and costs you the good leads too.
B32: Step 4 · Check the imports | C32: This is the step most teams skip and it is the one that pays. Import data tells you who is already buying containers of exactly your product, from whom, and how often. Fill group 3.
B33: Step 5 · Score and sort | C33: The score calculates itself. Work the A tier first, and put the C tier back into step 4 rather than throwing it away.
B34: Step 6 · Keep it clean | C34: Watch the duplicate flag and the completeness percentage. A list of 200 complete records beats 2,000 half-filled ones, every time.
B36: TWO RULES THAT KEEP THE FILE HONEST
B37: Record the basis | C37: Every estimate — revenue, import volume, opportunity — needs its source in the Import Data Source column or in Notes. An unattributed number becomes a fact by repetition, and then somebody quotes it to a customer.
B38: Date everything | C38: Contact data ages fast. Anything pulled more than six months ago should be re-verified before it is used.
B41: Colour key: | C41: Yellow = type here. Grey = calculated, do not type. Green/Blue/Amber/Red on Tier = A/B/C/D.
B42: Companion files: | C42: Export Order Tracker · Export Order Management SOP · Order Handover Sheet · Export Process Flowchart

Sheet LISTS
A1: MASTER DATA · DROPDOWN LISTS & COUNTRY REFERENCE
B2: RECORD STATUS | C2: BUSINESS TYPE | D2: PRODUCT CATEGORIES HANDLED | E2: CATEGORY MATCH | F2: OWN BRAND | G2: EMPLOYEES | H2: COMPANY SIZE | I2: IMPORTS? | J2: COMPETING ORIGIN SOURCED? | K2: IMPORT FREQUENCY | L2: DISPLACEMENT OPPORTUNITY | M2: IMPORT DATA SOURCE | N2: CONTAINER TYPE | O2: COUNTRY | P2: REGION | Q2: PREFERENTIAL ACCESS | R2: DECISION ROLE | S2: EMAIL STATUS | T2: SOURCE TOOL | U2: CONTACT FUNCTION | V2: VERIFIED? | W2: NEXT STEP
A3: Edit these lists to match how your team actually works. Every dropdown in the workbook reads from here. | B3: New | C3: Importer | D3: Houseware - general | E3: Core | F3: Own brand | G3: 1-10 | H3: Large | I3: Yes | J3: Yes | K3: Weekly | L3: High | M3: Volza | N3: 20ft GP | O3: Nigeria | P3: West Africa | Q3: AfCFTA | R3: Decision maker | S3: Valid | T3: Apify | U3: Purchasing | V3: Yes | W3: Enrich further
B4: Enriching | C4: Distributor | D4: Kitchenware | E4: Partial | F4: Private label | G4: 11-50 | H4: Medium | I4: No | J4: Partly | K4: Fortnightly | L4: Medium | M4: ImportGenius | N4: 40ft GP | O4: Ghana | P4: West Africa | Q4: ECOWAS | R4: Influencer | S4: Risky / catch-all | T4: Apollo | U4: Procurement | V4: No | W4: Verify email
B5: Enriched | C5: Wholesaler | D5: Food storage & containers | E5: None | F5: Third-party brands only | G5: 51-200 | H5: Small | I5: Unknown | J5: No | K5: Monthly | L5: Low | M5: Panjiva | N5: 40ft HC | O5: Ivory Coast | P5: West Africa | Q5: GSP | R5: Gatekeeper | S5: Invalid | T5: LinkedIn Sales Navigator | U5: Category buyer | V5: Partially | W5: Add to outreach list
B6: Verified | C6: Retail chain | D6: Bathware | F6: Mixed | G6: 201-500 | H6: Unknown | J6: Unknown | K6: Quarterly | L6: Unknown | M6: Customs / trade data | N6: LCL | O6: Senegal | P6: West Africa | Q6: Bilateral FTA | R6: End user | S6: Not found | T6: Claude research | U6: Import manager | W6: Send catalogue
B7: Qualified | C7: Supermarket group | D7: Buckets & basins | G7: 501-1000 | K7: Twice a year | M7: Buyer stated | N7: Mixed | O7: Benin | P7: West Africa | Q7: None | R7: Unknown | S7: Not checked | T7: Google / website | U7: Owner / Partner | W7: Qualify by call
B8: Disqualified | C8: Cash & carry | D8: Bins & cleaning | G8: 1000+ | K8: Ad hoc | M8: Website / social | N8: Unknown | O8: Togo | P8: West Africa | Q8: To be checked | T8: Trade directory | U8: MD / CEO | W8: Park
B9: Duplicate | C9: Buying house / Sourcing agent | D9: Coolers & insulated ware | G9: Unknown | K9: Unknown | M9: Inferred | O9: Burkina Faso | P9: West Africa | T9: Import data platform | U9: Sales | W9: Disqualify
B10: On hold | C10: E-commerce | D10: Water storage & jerrycans | M10: Not checked | O10: Mali | P10: West Africa | T10: Trade fair contact | U10: Operations
C11: Agent / Broker | D11: Plastic furniture | O11: Niger | P11: West Africa | T11: Referral | U11: Other
C12: Manufacturer (complementary range) | D12: Baby & toys | O12: Guinea | P12: West Africa | T12: Inbound enquiry
D13: Crates & industrial | O13: Sierra Leone | P13: West Africa
D14: Multiple / full range | O14: Liberia | P14: West Africa
O15: Gambia | P15: West Africa
O16: Cape Verde | P16: West Africa
O17: Mauritania | P17: West Africa
O18: Kenya | P18: East Africa
O19: Tanzania | P19: East Africa
O20: Uganda | P20: East Africa
O21: Rwanda | P21: East Africa
O22: Burundi | P22: East Africa
O23: Ethiopia | P23: East Africa
O24: Somalia | P24: East Africa
O25: Djibouti | P25: East Africa
O26: South Sudan | P26: East Africa
... O145: Suriname | P145: South America

Sheet SCORING
A1: ICP FIT SCORE — THE MODEL
A3: Every lead is scored out of 100 from six components. Edit the yellow point values to change what SACVIN considers a good lead — the whole LEAD MASTER sheet re-scores itself. Keep the component maximums adding up to 100 unless you deliberately want a different scale.
B5: 1. Business type | C5: max 25 | E5: Who actually buys containers. An importer or distributor outranks a single retailer.
B6: Importer | C6: 25
B7: Distributor | C7: 25
B8: Wholesaler | C8: 20
B9: Retail chain | C9: 18
B10: Supermarket group | C10: 18
B11: Cash & carry | C11: 16
B12: Buying house / Sourcing agent | C12: 14
B13: E-commerce | C13: 12
B14: Agent / Broker | C14: 10
B15: Manufacturer (complementary range) | C15: 8
B17: 2. Already importing? | C17: max 20 | E17: A company that already imports has the licence, the finance and the habit.
B18: Yes | C18: 20
B19: No | C19: 0
B20: Unknown | C20: 8
B22: 3. Sourcing from a competing origin | C22: max 20 | E22: China, India, Thailand, Turkey, Vietnam. If they buy there, SACVIN has something to displace.
B23: Yes | C23: 20
B24: Partly | C24: 14
B25: No | C25: 6
B26: Unknown | C26: 8
B28: 4. Company size | C28: max 15 | E28: Large: est. revenue above USD 20m · Medium: USD 5–20m · Small: below USD 5m.
B29: Large | C29: 15
B30: Medium | C30: 12
B31: Small | C31: 6
B32: Unknown | C32: 5
B34: 5. Category match | C34: max 10 | E34: Core: houseware, kitchenware, storage, bathware. Partial: adjacent plastics.
B35: Core | C35: 10
B36: Partial | C36: 6
B37: None | C37: 0
B39: 6. Contact quality | C39: max 10 | E39: Derived automatically from the contact columns on LEAD MASTER.
B40: Verified email + decision maker | C40: 10
B41: Verified email, other role | C41: 7
B42: Email present, not verified | C42: 4
B45: TIER THRESHOLDS — minimum score for each tier
B46: A — contact first | C46: 75
B47: B — good, work the list | C47: 60
B48: C — worth enriching further | C48: 40
B49: D — park or disqualify | C49: 0
...

Sheet LEAD MASTER
A1: 1. RECORD | E1: 2. COMPANY | U1: 3. IMPORT INTELLIGENCE | AG1: 4. COMMERCIAL FIT | AM1: 5. PRIMARY CONTACT | AV1: 6. SOURCE & DATA QUALITY | BC1: 7. SCORING (AUTO) — DO NOT TYPE HERE
A2: Lead ID | B2: Date Added | C2: Added By | D2: Record Status | E2: Company Name * | F2: Website * | G2: Country * | H2: Region | I2: City | J2: Business Type * | K2: Product Categories Handled | L2: Category Match * | M2: Own Brand / Private Label | N2: Year Established | O2: Employees | P2: Est. Annual Revenue (USD) | Q2: Company Size * | R2: Outlets / Branches | S2: LinkedIn Company URL | T2: What They Do (one line) | U2: Imports? * | V2: HS Codes Handled | W2: Current Source Countries | X2: Competing Origin Sourced? * | Y2: Known Current Suppliers | Z2: Est. Import Volume (ctnrs/yr) | AA2: Est. Import Value (USD/yr) | AB2: Typical Container Type | AC2: Import Frequency | AD2: Last Known Shipment | AE2: Displacement Opportunity | AF2: Import Data Source | AG2: Nearest Discharge Port | AH2: Preferential Access | AI2: Compliance / Certification | AJ2: Language | AK2: Priority SACVIN Products | AL2: Est. Opportunity (USD/yr) | AM2: Contact Name * | AN2: Job Title * | AO2: Decision Role | AP2: Email * | AQ2: Email Status | AR2: Phone * | AS2: WhatsApp | AT2: LinkedIn Profile URL | AU2: Contact Source Tool | AV2: Lead Source Tool | AW2: Date Pulled | AX2: Verified By | AY2: Verification Date | AZ2: Data Completeness | BA2: Duplicate Flag | BB2: Notes | BC2: Fit Score | BD2: Tier | BE2: Next Step
A3: SAC/LEAD/0001 | B3: 46246 | C3: R. Okafor | D3: Verified | E3: Kenmart Distributors Ltd | F3: kenmart.co.ke | G3: Kenya | H3: =IF($G3="","",IFERROR(INDEX(LISTS!$P$3:$P$145,MATCH($G3,LISTS!$O$3:$O$145,0)),"Other")) -> East Africa | I3: Nairobi | J3: Distributor | K3: Kitchenware, Food storage | L3: Core | M3: Third-party brands only | N3: 1998 | O3: 51-200 | P3: 12000000 | Q3: Medium | R3: 14 | S3: linkedin.com/company/kenmart | T3: Imports and distributes houseware to 400+ retailers across Kenya | U3: Yes | V3: 3924, 3923 | W3: China, India | X3: Yes | Y3: Ningbo Homelife Co. | Z3: 40 | AA3: 1800000 | AB3: 40ft HC | AC3: Monthly | AD3: 46221 | AE3: High | AF3: Volza | AG3: Mombasa | AH3: AfCFTA | AI3: PVoC required | AJ3: English | AK3: Coolers, jerrycans, buckets | AL3: 180000 | AM3: Grace Wanjiru | AN3: Head of Procurement | AO3: Decision maker | AP3: g.wanjiru@kenmart.co.ke | AQ3: Valid | AR3: +254 20 123 4567 | AS3: +254 722 000 000 | AT3: linkedin.com/in/gracewanjiru | AU3: Apollo | AV3: Apify | AW3: 46244 | AX3: R. Okafor | AY3: 46248 | AZ3: =IF($E3="","",COUNTA($E3,$F3,$G3,$J3,$L3,$Q3,$U3,$X3,$AM3,$AN3,$AP3,$AR3)/12) -> 1 | BA3: =IF($E3="","",IF(COUNTIF($E$3:$E$402,$E3)>1,"DUPLICATE","")) | BB3: Import value from Volza, 12 months to Jun-26. Buys monthly. | BC3: =IF($E3="","",IFERROR(INDEX(SCORING!$C$6:$C$15,MATCH($J3,SCORING!$B$6:$B$15,0)),0)+IFERROR(INDEX(SCORING!$C$18:$C$20,MATCH($U3,SCORING!$B$18:$B$20,0)),0)+IFERROR(INDEX(SCORING!$C$23:$C$26,MATCH($X3,SCORING!$B$23:$B$26,0)),0)+IFERROR(INDEX(SCORING!$C$29:$C$32,MATCH($Q3,SCORING!$B$29:$B$32,0)),0)+IFERROR(INDEX(SCORING!$C$35:$C$37,MATCH($L3,SCORING!$B$35:$B$37,0)),0)+IF($AP3="",0,IF(AND($AQ3="Valid",$AO3="Decision maker"),SCORING!$C$40,IF($AQ3="Valid",SCORING!$C$41,SCORING!$C$42)))) -> 97 | BD3: =IF($BC3="","",IF($BC3>=SCORING!$C$46,"A",IF($BC3>=SCORING!$C$47,"B",IF($BC3>=SCORING!$C$48,"C","D")))) -> A | BE3: Add to outreach list
A4: SAC/LEAD/0002 | B4: 46251 | C4: R. Okafor | D4: Enriching | E4: Gulf Home Trading LLC | F4: gulfhome.ae | G4: UAE | H4: =IF($G4="","",IFERROR(INDEX(LISTS!$P$3:$P$145,MATCH($G4,LISTS!$O$3:$O$145,0)),"Other")) -> Middle East / Gulf | I4: Dubai | J4: Importer | K4: Multiple / full range | L4: Core | M4: Private label | O4: 11-50 | P4: 6500000 | Q4: Medium | S4: linkedin.com/company/gulfhome | T4: Re-exports houseware from Jebel Ali into the wider Gulf and East Africa | U4: Yes | V4: 3924 | W4: China, Turkey | X4: Yes | Z4: 22 | AB4: 40ft HC | AC4: Quarterly | AE4: Medium | AF4: Not checked | AG4: Jebel Ali | AH4: To be checked | AJ4: English / Arabic | AK4: Storage range, bathware | AM4: Omar Haddad | AN4: Purchase Manager | AO4: Influencer | AP4: omar@gulfhome.ae | AQ4: Valid | AR4: +971 4 555 1234 | AU4: LinkedIn Sales Navigator | AV4: LinkedIn Sales Navigator | AW4: 46250 | AZ4: =IF($E4="","",COUNTA($E4,$F4,$G4,$J4,$L4,$Q4,$U4,$X4,$AM4,$AN4,$AP4,$AR4)/12) -> 1 | BA4: =IF($E4="","",IF(COUNTIF($E$3:$E$402,$E4)>1,"DUPLICATE","")) | BB4: Import volumes still to be pulled from Volza. Owner is the real decision maker. | BC4: =IF($E4="","",IFERROR(INDEX(SCORING!$C$6:$C$15,MATCH($J4,SCORING!$B$6:$B$15,0)),0)+IFERROR(INDEX(SCORING!$C$18:$C$20,MATCH($U4,SCORING!$B$18:$B$20,0)),0)+IFERROR(INDEX(SCORING!$C$23:$C$26,MATCH($X4,SCORING!$B$23:$B$26,0)),0)+IFERROR(INDEX(SCORING!$C$29:$C$32,MATCH($Q4,SCORING!$B$29:$B$32,0)),0)+IFERROR(INDEX(SCORING!$C$35:$C$37,MATCH($L4,SCORING!$B$35:$B$37,0)),0)+IF($AP4="",0,IF(AND($AQ4="Valid",$AO4="Decision maker"),SCORING!$C$40,IF($AQ4="Valid",SCORING!$C$41,SCORING!$C$42)))) -> 94 | BD4: =IF($BC4="","",IF($BC4>=SCORING!$C$46,"A",IF($BC4>=SCORING!$C$47,"B",IF($BC4>=SCORING!$C$48,"C","D")))) -> A | BE4: Enrich further
A5: SAC/LEAD/0003 | B5: 46256 | C5: S. Menon | D5: New | E5: Suva Homeware Imports Pte | G5: Fiji | H5: =IF($G5="","",IFERROR(INDEX(LISTS!$P$3:$P$145,MATCH($G5,LISTS!$O$3:$O$145,0)),"Other")) -> Oceania | I5: Suva | J5: Wholesaler | K5: Houseware - general | L5: Partial | O5: 11-50 | Q5: Small | U5: Unknown | X5: Unknown | AF5: Not checked | AG5: Suva | AH5: To be checked | AJ5: English | AM5: Anil Prasad | AN5: Buyer | AO5: Unknown | AP5: anil@suvahomeware.com.fj | AQ5: Risky / catch-all | AU5: Apollo | AV5: Trade directory | AW5: 46256 | AZ5: =IF($E5="","",COUNTA($E5,$F5,$G5,$J5,$L5,$Q5,$U5,$X5,$AM5,$AN5,$AP5,$AR5)/12) -> 0.83333333 | BA5: =IF($E5="","",IF(COUNTIF($E$3:$E$402,$E5)>1,"DUPLICATE","")) | BB5: Thin record — website and phone still missing, import status unknown. Verify before spending more time. | BC5: =IF($E5="","",IFERROR(INDEX(SCORING!$C$6:$C$15,MATCH($J5,SCORING!$B$6:$B$15,0)),0)+IFERROR(INDEX(SCORING!$C$18:$C$20,MATCH($U5,SCORING!$B$18:$B$20,0)),0)+IFERROR(INDEX(SCORING!$C$23:$C$26,MATCH($X5,SCORING!$B$23:$B$26,0)),0)+IFERROR(INDEX(SCORING!$C$29:$C$32,MATCH($Q5,SCORING!$B$29:$B$32,0)),0)+IFERROR(INDEX(SCORING!$C$35:$C$37,MATCH($L5,SCORING!$B$35:$B$37,0)),0)+IF($AP5="",0,IF(AND($AQ5="Valid",$AO5="Decision maker"),SCORING!$C$40,IF($AQ5="Valid",SCORING!$C$41,SCORING!$C$42)))) -> 52 | BD5: =IF($BC5="","",IF($BC5>=SCORING!$C$46,"A",IF($BC5>=SCORING!$C$47,"B",IF($BC5>=SCORING!$C$48,"C","D")))) -> C | BE5: Verify email
H6: =IF($G6="","",IFERROR(INDEX(LISTS!$P$3:$P$145,MATCH($G6,LISTS!$O$3:$O$145,0)),"Other")) | AZ6: =IF($E6="","",COUNTA($E6,$F6,$G6,$J6,$L6,$Q6,$U6,$X6,$AM6,$AN6,$AP6,$AR6)/12) | BA6: =IF($E6="","",IF(COUNTIF($E$3:$E$402,$E6)>1,"DUPLICATE","")) | BC6: =IF($E6="","",IFERROR(INDEX(SCORING!$C$6:$C$15,MATCH($J6,SCORING!$B$6:$B$15,0)),0)+IFERROR(INDEX(SCORING!$C$18:$C$20,MATCH($U6,SCORING!$B$18:$B$20,0)),0)+IFERROR(INDEX(SCORING!$C$23:$C$26,MATCH($X6,SCORING!$B$23:$B$26,0)),0)+IFERROR(INDEX(SCORING!$C$29:$C$32,MATCH($Q6,SCORING!$B$29:$B$32,0)),0)+IFERROR(INDEX(SCORING!$C$35:$C$37,MATCH($L6,SCORING!$B$35:$B$37,0)),0)+IF($AP6="",0,IF(AND($AQ6="Valid",$AO6="Decision maker"),SCORING!$C$40,IF($AQ6="Valid",SCORING!$C$41,SCORING!$C$42)))) | BD6: =IF($BC6="","",IF($BC6>=SCORING!$C$46,"A",IF($BC6>=SCORING!$C$47,"B",IF($BC6>=SCORING!$C$48,"C","D"))))
H7: =IF($G7="","",IFERROR(INDEX(LISTS!$P$3:$P$145,MATCH($G7,LISTS!$O$3:$O$145,0)),"Other")) | AZ7: =IF($E7="","",COUNTA($E7,$F7,$G7,$J7,$L7,$Q7,$U7,$X7,$AM7,$AN7,$AP7,$AR7)/12) | BA7: =IF($E7="","",IF(COUNTIF($E$3:$E$402,$E7)>1,"DUPLICATE","")) | BC7: =IF($E7="","",IFERROR(INDEX(SCORING!$C$6:$C$15,MATCH($J7,SCORING!$B$6:$B$15,0)),0)+IFERROR(INDEX(SCORING!$C$18:$C$20,MATCH($U7,SCORING!$B$18:$B$20,0)),0)+IFERROR(INDEX(SCORING!$C$23:$C$26,MATCH($X7,SCORING!$B$23:$B$26,0)),0)+IFERROR(INDEX(SCORING!$C$29:$C$32,MATCH($Q7,SCORING!$B$29:$B$32,0)),0)+IFERROR(INDEX(SCORING!$C$35:$C$37,MATCH($L7,SCORING!$B$35:$B$37,0)),0)+IF($AP7="",0,IF(AND($AQ7="Valid",$AO7="Decision maker"),SCORING!$C$40,IF($AQ7="Valid",SCORING!$C$41,SCORING!$C$42)))) | BD7: =IF($BC7="","",IF($BC7>=SCORING!$C$46,"A",IF($BC7>=SCORING!$C$47,"B",IF($BC7>=SCORING!$C$48,"C","D"))))
H8: =IF($G8="","",IFERROR(INDEX(LISTS!$P$3:$P$145,MATCH($G8,LISTS!$O$3:$O$145,0)),"Other")) | AZ8: =IF($E8="","",COUNTA($E8,$F8,$G8,$J8,$L8,$Q8,$U8,$X8,$AM8,$AN8,$AP8,$AR8)/12) | BA8: =IF($E8="","",IF(COUNTIF($E$3:$E$402,$E8)>1,"DUPLICATE","")) | BC8: =IF($E8="","",IFERROR(INDEX(SCORING!$C$6:$C$15,MATCH($J8,SCORING!$B$6:$B$15,0)),0)+IFERROR(INDEX(SCORING!$C$18:$C$20,MATCH($U8,SCORING!$B$18:$B$20,0)),0)+IFERROR(INDEX(SCORING!$C$23:$C$26,MATCH($X8,SCORING!$B$23:$B$26,0)),0)+IFERROR(INDEX(SCORING!$C$29:$C$32,MATCH($Q8,SCORING!$B$29:$B$32,0)),0)+IFERROR(INDEX(SCORING!$C$35:$C$37,MATCH($L8,SCORING!$B$35:$B$37,0)),0)+IF($AP8="",0,IF(AND($AQ8="Valid",$AO8="Decision maker"),SCORING!$C$40,IF($AQ8="Valid",SCORING!$C$41,SCORING!$C$42)))) | BD8: =IF($BC8="","",IF($BC8>=SCORING!$C$46,"A",IF($BC8>=SCORING!$C$47,"B",IF($BC8>=SCORING!$C$48,"C","D"))))
H9: =IF($G9="","",IFERROR(INDEX(LISTS!$P$3:$P$145,MATCH($G9,LISTS!$O$3:$O$145,0)),"Other")) | AZ9: =IF($E9="","",COUNTA($E9,$F9,$G9,$J9,$L9,$Q9,$U9,$X9,$AM9,$AN9,$AP9,$AR9)/12) | BA9: =IF($E9="","",IF(COUNTIF($E$3:$E$402,$E9)>1,"DUPLICATE","")) | BC9: =IF($E9="","",IFERROR(INDEX(SCORING!$C$6:$C$15,MATCH($J9,SCORING!$B$6:$B$15,0)),0)+IFERROR(INDEX(SCORING!$C$18:$C$20,MATCH($U9,SCORING!$B$18:$B$20,0)),0)+IFERROR(INDEX(SCORING!$C$23:$C$26,MATCH($X9,SCORING!$B$23:$B$26,0)),0)+IFERROR(INDEX(SCORING!$C$29:$C$32,MATCH($Q9,SCORING!$B$29:$B$32,0)),0)+IFERROR(INDEX(SCORING!$C$35:$C$37,MATCH($L9,SCORING!$B$35:$B$37,0)),0)+IF($AP9="",0,IF(AND($AQ9="Valid",$AO9="Decision maker"),SCORING!$C$40,IF($AQ9="Valid",SCORING!$C$41,SCORING!$C$42)))) | BD9: =IF($BC9="","",IF($BC9>=SCORING!$C$46,"A",IF($BC9>=SCORING!$C$47,"B",IF($BC9>=SCORING!$C$48,"C","D"))))
H10: =IF($G10="","",IFERROR(INDEX(LISTS!$P$3:$P$145,MATCH($G10,LISTS!$O$3:$O$145,0)),"Other")) | AZ10: =IF($E10="","",COUNTA($E10,$F10,$G10,$J10,$L10,$Q10,$U10,$X10,$AM10,$AN10,$AP10,$AR10)/12) | BA10: =IF($E10="","",IF(COUNTIF($E$3:$E$402,$E10)>1,"DUPLICATE","")) | BC10: =IF($E10="","",IFERROR(INDEX(SCORING!$C$6:$C$15,MATCH($J10,SCORING!$B$6:$B$15,0)),0)+IFERROR(INDEX(SCORING!$C$18:$C$20,MATCH($U10,SCORING!$B$18:$B$20,0)),0)+IFERROR(INDEX(SCORING!$C$23:$C$26,MATCH($X10,SCORING!$B$23:$B$26,0)),0)+IFERROR(INDEX(SCORING!$C$29:$C$32,MATCH($Q10,SCORING!$B$29:$B$32,0)),0)+IFERROR(INDEX(SCORING!$C$35:$C$37,MATCH($L10,SCORING!$B$35:$B$37,0)),0)+IF($AP10="",0,IF(AND($AQ10="Valid",$AO10="Decision maker"),SCORING!$C$40,IF($AQ10="Valid",SCORING!$C$41,SCORING!$C$42)))) | BD10: =IF($BC10="","",IF($BC10>=SCORING!$C$46,"A",IF($BC10>=SCORING!$C$47,"B",IF($BC10>=SCORING!$C$48,"C","D"))))
H11: =IF($G11="","",IFERROR(INDEX(LISTS!$P$3:$P$145,MATCH($G11,LISTS!$O$3:$O$145,0)),"Other")) | AZ11: =IF($E11="","",COUNTA($E11,$F11,$G11,$J11,$L11,$Q11,$U11,$X11,$AM11,$AN11,$AP11,$AR11)/12) | BA11: =IF($E11="","",IF(COUNTIF($E$3:$E$402,$E11)>1,"DUPLICATE","")) | BC11: =IF($E11="","",IFERROR(INDEX(SCORING!$C$6:$C$15,MATCH($J11,SCORING!$B$6:$B$15,0)),0)+IFERROR(INDEX(SCORING!$C$18:$C$20,MATCH($U11,SCORING!$B$18:$B$20,0)),0)+IFERROR(INDEX(SCORING!$C$23:$C$26,MATCH($X11,SCORING!$B$23:$B$26,0)),0)+IFERROR(INDEX(SCORING!$C$29:$C$32,MATCH($Q11,SCORING!$B$29:$B$32,0)),0)+IFERROR(INDEX(SCORING!$C$35:$C$37,MATCH($L11,SCORING!$B$35:$B$37,0)),0)+IF($AP11="",0,IF(AND($AQ11="Valid",$AO11="Decision maker"),SCORING!$C$40,IF($AQ11="Valid",SCORING!$C$41,SCORING!$C$42)))) | BD11: =IF($BC11="","",IF($BC11>=SCORING!$C$46,"A",IF($BC11>=SCORING!$C$47,"B",IF($BC11>=SCORING!$C$48,"C","D"))))
H12: =IF($G12="","",IFERROR(INDEX(LISTS!$P$3:$P$145,MATCH($G12,LISTS!$O$3:$O$145,0)),"Other")) | AZ12: =IF($E12="","",COUNTA($E12,$F12,$G12,$J12,$L12,$Q12,$U12,$X12,$AM12,$AN12,$AP12,$AR12)/12) | BA12: =IF($E12="","",IF(COUNTIF($E$3:$E$402,$E12)>1,"DUPLICATE","")) | BC12: =IF($E12="","",IFERROR(INDEX(SCORING!$C$6:$C$15,MATCH($J12,SCORING!$B$6:$B$15,0)),0)+IFERROR(INDEX(SCORING!$C$18:$C$20,MATCH($U12,SCORING!$B$18:$B$20,0)),0)+IFERROR(INDEX(SCORING!$C$23:$C$26,MATCH($X12,SCORING!$B$23:$B$26,0)),0)+IFERROR(INDEX(SCORING!$C$29:$C$32,MATCH($Q12,SCORING!$B$29:$B$32,0)),0)+IFERROR(INDEX(SCORING!$C$35:$C$37,MATCH($L12,SCORING!$B$35:$B$37,0)),0)+IF($AP12="",0,IF(AND($AQ12="Valid",$AO12="Decision maker"),SCORING!$C$40,IF($AQ12="Valid",SCORING!$C$41,SCORING!$C$42)))) | BD12: =IF($BC12="","",IF($BC12>=SCORING!$C$46,"A",IF($BC12>=SCORING!$C$47,"B",IF($BC12>=SCORING!$C$48,"C","D"))))
H13: =IF($G13="","",IFERROR(INDEX(LISTS!$P$3:$P$145,MATCH($G13,LISTS!$O$3:$O$145,0)),"Other")) | AZ13: =IF($E13="","",COUNTA($E13,$F13,$G13,$J13,$L13,$Q13,$U13,$X13,$AM13,$AN13,$AP13,$AR13)/12) | BA13: =IF($E13="","",IF(COUNTIF($E$3:$E$402,$E13)>1,"DUPLICATE","")) | BC13: =IF($E13="","",IFERROR(INDEX(SCORING!$C$6:$C$15,MATCH($J13,SCORING!$B$6:$B$15,0)),0)+IFERROR(INDEX(SCORING!$C$18:$C$20,MATCH($U13,SCORING!$B$18:$B$20,0)),0)+IFERROR(INDEX(SCORING!$C$23:$C$26,MATCH($X13,SCORING!$B$23:$B$26,0)),0)+IFERROR(INDEX(SCORING!$C$29:$C$32,MATCH($Q13,SCORING!$B$29:$B$32,0)),0)+IFERROR(INDEX(SCORING!$C$35:$C$37,MATCH($L13,SCORING!$B$35:$B$37,0)),0)+IF($AP13="",0,IF(AND($AQ13="Valid",$AO13="Decision maker"),SCORING!$C$40,IF($AQ13="Valid",SCORING!$C$41,SCORING!$C$42)))) | BD13: =IF($BC13="","",IF($BC13>=SCORING!$C$46,"A",IF($BC13>=SCORING!$C$47,"B",IF($BC13>=SCORING!$C$48,"C","D"))))
H14: =IF($G14="","",IFERROR(INDEX(LISTS!$P$3:$P$145,MATCH($G14,LISTS!$O$3:$O$145,0)),"Other")) | AZ14: =IF($E14="","",COUNTA($E14,$F14,$G14,$J14,$L14,$Q14,$U14,$X14,$AM14,$AN14,$AP14,$AR14)/12) | BA14: =IF($E14="","",IF(COUNTIF($E$3:$E$402,$E14)>1,"DUPLICATE","")) | BC14: =IF($E14="","",IFERROR(INDEX(SCORING!$C$6:$C$15,MATCH($J14,SCORING!$B$6:$B$15,0)),0)+IFERROR(INDEX(SCORING!$C$18:$C$20,MATCH($U14,SCORING!$B$18:$B$20,0)),0)+IFERROR(INDEX(SCORING!$C$23:$C$26,MATCH($X14,SCORING!$B$23:$B$26,0)),0)+IFERROR(INDEX(SCORING!$C$29:$C$32,MATCH($Q14,SCORING!$B$29:$B$32,0)),0)+IFERROR(INDEX(SCORING!$C$35:$C$37,MATCH($L14,SCORING!$B$35:$B$37,0)),0)+IF($AP14="",0,IF(AND($AQ14="Valid",$AO14="Decision maker"),SCORING!$C$40,IF($AQ14="Valid",SCORING!$C$41,SCORING!$C$42)))) | BD14: =IF($BC14="","",IF($BC14>=SCORING!$C$46,"A",IF($BC14>=SCORING!$C$47,"B",IF($BC14>=SCORING!$C$48,"C","D"))))
H15: =IF($G15="","",IFERROR(INDEX(LISTS!$P$3:$P$145,MATCH($G15,LISTS!$O$3:$O$145,0)),"Other")) | AZ15: =IF($E15="","",COUNTA($E15,$F15,$G15,$J15,$L15,$Q15,$U15,$X15,$AM15,$AN15,$AP15,$AR15)/12) | BA15: =IF($E15="","",IF(COUNTIF($E$3:$E$402,$E15)>1,"DUPLICATE","")) | BC15: =IF($E15="","",IFERROR(INDEX(SCORING!$C$6:$C$15,MATCH($J15,SCORING!$B$6:$B$15,0)),0)+IFERROR(INDEX(SCORING!$C$18:$C$20,MATCH($U15,SCORING!$B$18:$B$20,0)),0)+IFERROR(INDEX(SCORING!$C$23:$C$26,MATCH($X15,SCORING!$B$23:$B$26,0)),0)+IFERROR(INDEX(SCORING!$C$29:$C$32,MATCH($Q15,SCORING!$B$29:$B$32,0)),0)+IFERROR(INDEX(SCORING!$C$35:$C$37,MATCH($L15,SCORING!$B$35:$B$37,0)),0)+IF($AP15="",0,IF(AND($AQ15="Valid",$AO15="Decision maker"),SCORING!$C$40,IF($AQ15="Valid",SCORING!$C$41,SCORING!$C$42)))) | BD15: =IF($BC15="","",IF($BC15>=SCORING!$C$46,"A",IF($BC15>=SCORING!$C$47,"B",IF($BC15>=SCORING!$C$48,"C","D"))))
H16: =IF($G16="","",IFERROR(INDEX(LISTS!$P$3:$P$145,MATCH($G16,LISTS!$O$3:$O$145,0)),"Other")) | AZ16: =IF($E16="","",COUNTA($E16,$F16,$G16,$J16,$L16,$Q16,$U16,$X16,$AM16,$AN16,$AP16,$AR16)/12) | BA16: =IF($E16="","",IF(COUNTIF($E$3:$E$402,$E16)>1,"DUPLICATE","")) | BC16: =IF($E16="","",IFERROR(INDEX(SCORING!$C$6:$C$15,MATCH($J16,SCORING!$B$6:$B$15,0)),0)+IFERROR(INDEX(SCORING!$C$18:$C$20,MATCH($U16,SCORING!$B$18:$B$20,0)),0)+IFERROR(INDEX(SCORING!$C$23:$C$26,MATCH($X16,SCORING!$B$23:$B$26,0)),0)+IFERROR(INDEX(SCORING!$C$29:$C$32,MATCH($Q16,SCORING!$B$29:$B$32,0)),0)+IFERROR(INDEX(SCORING!$C$35:$C$37,MATCH($L16,SCORING!$B$35:$B$37,0)),0)+IF($AP16="",0,IF(AND($AQ16="Valid",$AO16="Decision maker"),SCORING!$C$40,IF($AQ16="Valid",SCORING!$C$41,SCORING!$C$42)))) | BD16: =IF($BC16="","",IF($BC16>=SCORING!$C$46,"A",IF($BC16>=SCORING!$C$47,"B",IF($BC16>=SCORING!$C$48,"C","D"))))
H17: =IF($G17="","",IFERROR(INDEX(LISTS!$P$3:$P$145,MATCH($G17,LISTS!$O$3:$O$145,0)),"Other")) | AZ17: =IF($E17="","",COUNTA($E17,$F17,$G17,$J17,$L17,$Q17,$U17,$X17,$AM17,$AN17,$AP17,$AR17)/12) | BA17: =IF($E17="","",IF(COUNTIF($E$3:$E$402,$E17)>1,"DUPLICATE","")) | BC17: =IF($E17="","",IFERROR(INDEX(SCORING!$C$6:$C$15,MATCH($J17,SCORING!$B$6:$B$15,0)),0)+IFERROR(INDEX(SCORING!$C$18:$C$20,MATCH($U17,SCORING!$B$18:$B$20,0)),0)+IFERROR(INDEX(SCORING!$C$23:$C$26,MATCH($X17,SCORING!$B$23:$B$26,0)),0)+IFERROR(INDEX(SCORING!$C$29:$C$32,MATCH($Q17,SCORING!$B$29:$B$32,0)),0)+IFERROR(INDEX(SCORING!$C$35:$C$37,MATCH($L17,SCORING!$B$35:$B$37,0)),0)+IF($AP17="",0,IF(AND($AQ17="Valid",$AO17="Decision maker"),SCORING!$C$40,IF($AQ17="Valid",SCORING!$C$41,SCORING!$C$42)))) | BD17: =IF($BC17="","",IF($BC17>=SCORING!$C$46,"A",IF($BC17>=SCORING!$C$47,"B",IF($BC17>=SCORING!$C$48,"C","D"))))
... H402: =IF($G402="","",IFERROR(INDEX(LISTS!$P$3:$P$145,MATCH($G402,LISTS!$O$3:$O$145,0)),"Other")) | AZ402: =IF($E402="","",COUNTA($E402,$F402,$G402,$J402,$L402,$Q402,$U402,$X402,$AM402,$AN402,$AP402,$AR402)/12) | BA402: =IF($E402="","",IF(COUNTIF($E$3:$E$402,$E402)>1,"DUPLICATE","")) | BC402: =IF($E402="","",IFERROR(INDEX(SCORING!$C$6:$C$15,MATCH($J402,SCORING!$B$6:$B$15,0)),0)+IFERROR(INDEX(SCORING!$C$18:$C$20,MATCH($U402,SCORING!$B$18:$B$20,0)),0)+IFERROR(INDEX(SCORING!$C$23:$C$26,MATCH($X402,SCORING!$B$23:$B$26,0)),0)+IFERROR(INDEX(SCORING!$C$29:$C$32,MATCH($Q402,SCORING!$B$29:$B$32,0)),0)+IFERROR(INDEX(SCORING!$C$35:$C$37,MATCH($L402,SCORING!$B$35:$B$37,0)),0)+IF($AP402="",0,IF(AND($AQ402="Valid",$AO402="Decision maker"),SCORING!$C$40,IF($AQ402="Valid",SCORING!$C$41,SCORING!$C$42)))) | BD402: =IF($BC402="","",IF($BC402>=SCORING!$C$46,"A",IF($BC402>=SCORING!$C$47,"B",IF($BC402>=SCORING!$C$48,"C","D"))))

Sheet CONTACTS
A1: CONTACTS — ONE ROW PER PERSON
A2: Use this when a company has more than one buyer worth knowing. Enter the Lead ID and the company name fills itself. The primary contact still belongs on the LEAD MASTER sheet — this is for the rest.
A4: Contact ID | B4: Lead ID | C4: Company Name | D4: Full Name | E4: Job Title | F4: Function | G4: Decision Role | H4: Email | I4: Email Status | J4: Phone | K4: WhatsApp | L4: LinkedIn Profile URL | M4: Language | N4: Best Time to Call | O4: Source Tool | P4: Date Pulled | Q4: Verified? | R4: Notes
A5: SAC/CON/0001 | B5: SAC/LEAD/0001 | C5: =IF($B5="","",IFERROR(INDEX('LEAD MASTER'!$E$3:$E$402,MATCH($B5,'LEAD MASTER'!$A$3:$A$402,0)),"Lead ID not found")) -> Kenmart Distributors Ltd | D5: David Kamau | E5: Managing Director | F5: MD / CEO | G5: Decision maker | H5: d.kamau@kenmart.co.ke | I5: Valid | J5: +254 20 123 4560 | M5: English | N5: 09:00-12:00 EAT | O5: LinkedIn Sales Navigator | P5: 46248 | Q5: Yes | R5: Signs off anything above USD 50k
A6: SAC/CON/0002 | B6: SAC/LEAD/0002 | C6: =IF($B6="","",IFERROR(INDEX('LEAD MASTER'!$E$3:$E$402,MATCH($B6,'LEAD MASTER'!$A$3:$A$402,0)),"Lead ID not found")) -> Gulf Home Trading LLC | D6: Fatima Al Balushi | E6: Category Buyer - Houseware | F6: Category buyer | G6: Influencer | H6: fatima@gulfhome.ae | I6: Valid | J6: +971 4 555 1240 | M6: English / Arabic | N6: 10:00-15:00 GST | O6: Apollo | P6: 46251 | Q6: No | R6: Reports to the owner
C7: =IF($B7="","",IFERROR(INDEX('LEAD MASTER'!$E$3:$E$402,MATCH($B7,'LEAD MASTER'!$A$3:$A$402,0)),"Lead ID not found"))
C8: =IF($B8="","",IFERROR(INDEX('LEAD MASTER'!$E$3:$E$402,MATCH($B8,'LEAD MASTER'!$A$3:$A$402,0)),"Lead ID not found"))
C9: =IF($B9="","",IFERROR(INDEX('LEAD MASTER'!$E$3:$E$402,MATCH($B9,'LEAD MASTER'!$A$3:$A$402,0)),"Lead ID not found"))
C10: =IF($B10="","",IFERROR(INDEX('LEAD MASTER'!$E$3:$E$402,MATCH($B10,'LEAD MASTER'!$A$3:$A$402,0)),"Lead ID not found"))
C11: =IF($B11="","",IFERROR(INDEX('LEAD MASTER'!$E$3:$E$402,MATCH($B11,'LEAD MASTER'!$A$3:$A$402,0)),"Lead ID not found"))
C12: =IF($B12="","",IFERROR(INDEX('LEAD MASTER'!$E$3:$E$402,MATCH($B12,'LEAD MASTER'!$A$3:$A$402,0)),"Lead ID not found"))
C13: =IF($B13="","",IFERROR(INDEX('LEAD MASTER'!$E$3:$E$402,MATCH($B13,'LEAD MASTER'!$A$3:$A$402,0)),"Lead ID not found"))
C14: =IF($B14="","",IFERROR(INDEX('LEAD MASTER'!$E$3:$E$402,MATCH($B14,'LEAD MASTER'!$A$3:$A$402,0)),"Lead ID not found"))
C15: =IF($B15="","",IFERROR(INDEX('LEAD MASTER'!$E$3:$E$402,MATCH($B15,'LEAD MASTER'!$A$3:$A$402,0)),"Lead ID not found"))
C16: =IF($B16="","",IFERROR(INDEX('LEAD MASTER'!$E$3:$E$402,MATCH($B16,'LEAD MASTER'!$A$3:$A$402,0)),"Lead ID not found"))
C17: =IF($B17="","",IFERROR(INDEX('LEAD MASTER'!$E$3:$E$402,MATCH($B17,'LEAD MASTER'!$A$3:$A$402,0)),"Lead ID not found"))
C18: =IF($B18="","",IFERROR(INDEX('LEAD MASTER'!$E$3:$E$402,MATCH($B18,'LEAD MASTER'!$A$3:$A$402,0)),"Lead ID not found"))
... C604: =IF($B604="","",IFERROR(INDEX('LEAD MASTER'!$E$3:$E$402,MATCH($B604,'LEAD MASTER'!$A$3:$A$402,0)),"Lead ID not found"))

Sheet ENRICHMENT GUIDE
A1: ENRICHMENT GUIDE — WHAT EVERY FIELD MEANS AND WHERE TO GET IT
A2: Hand this to whoever does the enrichment. Fields marked MANDATORY are the twelve that the Data Completeness percentage measures — a record is not usable until they are filled.
A4: Col | B4: Field | C4: Group | D4: Mandatory | E4: Where to get it | F4: What it means | G4: Example
A5: A | B5: Lead ID | C5: 1. RECORD | E5: Manual | F5: Unique reference. Keep the format fixed so it can be cited anywhere. | G5: SAC/LEAD/0001
A6: B | B6: Date Added | C6: 1. RECORD | E6: Manual | F6: The day the record entered this file. | G6: 12-Aug-26
A7: C | B7: Added By | C7: 1. RECORD | E7: Manual | F7: Who created the record — so questions have an owner. | G7: R. Okafor
A8: D | B8: Record Status | C8: 1. RECORD | E8: Dropdown | F8: Where the record is in the enrichment process, not the sales process. | G8: Enriched
A9: E | B9: Company Name | C9: 2. COMPANY | D9: MANDATORY | E9: Apify / Apollo | F9: Trading name as the market knows it. Used for the duplicate check, so keep it consistent. | G9: Kenmart Distributors Ltd
A10: F | B10: Website | C10: 2. COMPANY | D10: MANDATORY | E10: Apify / Apollo | F10: Root domain. The single most useful field for verifying everything else. | G10: kenmart.co.ke
A11: G | B11: Country | C11: 2. COMPANY | D11: MANDATORY | E11: Apify / Apollo | F11: Must be spelled exactly as on the LISTS country table or the Region will not resolve. | G11: Kenya
A12: H | B12: Region | C12: 2. COMPANY | D12: auto | E12: Auto | F12: Looked up from the country. Do not type here. | G12: East Africa
A13: I | B13: City | C13: 2. COMPANY | E13: Apify / Apollo | F13: Helps judge distance from the discharge port and time zone for calling. | G13: Nairobi
A14: J | B14: Business Type | C14: 2. COMPANY | D14: MANDATORY | E14: Dropdown | F14: What they actually do. The single biggest driver of the fit score. | G14: Distributor
A15: K | B15: Product Categories Handled | C15: 2. COMPANY | E15: Website / Apify | F15: What they already sell. Free text or pick from the dropdown; list more than one if true. | G15: Kitchenware, Food storage
A16: L | B16: Category Match | C16: 2. COMPANY | D16: MANDATORY | E16: Judgement | F16: Core / Partial / None against SACVIN's range. Scored. | G16: Core
A17: M | B17: Own Brand / Private Label | C17: 2. COMPANY | E17: Website | F17: Private-label buyers are higher-volume but need artwork and MOQ discipline. | G17: Private label
A18: N | B18: Year Established | C18: 2. COMPANY | E18: Apollo / website | F18: A proxy for stability. Under three years old deserves a credit check. | G18: 1998
A19: O | B19: Employees | C19: 2. COMPANY | E19: Apollo / LinkedIn | F19: Band, not an exact number. | G19: 51-200
A20: P | B20: Est. Annual Revenue (USD) | C20: 2. COMPANY | E20: Apollo / Claude research | F20: Best available estimate. Record the basis in Notes if it is an inference. | G20: 12000000
A21: Q | B21: Company Size | C21: 2. COMPANY | D21: MANDATORY | E21: Dropdown | F21: Large / Medium / Small, banded from revenue. Scored. | G21: Medium
A22: R | B22: Outlets / Branches | C22: 2. COMPANY | E22: Website | F22: For retail and cash & carry — a direct read on offtake. | G22: 14
A23: S | B23: LinkedIn Company URL | C23: 2. COMPANY | E23: Sales Navigator | F23: The company page, not a person. | G23: linkedin.com/company/...
A24: T | B24: What They Do (one line) | C24: 2. COMPANY | E24: Claude research | F24: One sentence a salesperson can read before dialling. | G24: Imports and distributes houseware to 400+ retailers across Kenya
A25: U | B25: Imports? | C25: 3. IMPORT INTELLIGENCE | D25: MANDATORY | E25: Import data / website | F25: Do they import directly, or only buy locally? Scored heavily. | G25: Yes
A26: V | B26: HS Codes Handled | C26: 3. IMPORT INTELLIGENCE | E26: Import data | F26: Plastic houseware sits mainly in 3924, plus 3922, 3923, 3926. | G26: 3924, 3923
A27: W | B27: Current Source Countries | C27: 3. IMPORT INTELLIGENCE | E27: Import data | F27: Where they buy today. Free text, comma separated. | G27: China, India
A28: X | B28: Competing Origin Sourced? | C28: 3. IMPORT INTELLIGENCE | D28: MANDATORY | E28: Derived | F28: Yes if they source from China, India, Thailand, Turkey or Vietnam. Scored. | G28: Yes
A29: Y | B29: Known Current Suppliers | C29: 3. IMPORT INTELLIGENCE | E29: Import data | F29: Named suppliers you would be displacing. Gold dust for the first call. | G29: Ningbo Homelife Co.
A30: Z | B30: Est. Import Volume (ctnrs/yr) | C30: 3. IMPORT INTELLIGENCE | E30: Import data | F30: Containers per year, all categories. | G30: 40
A31: AA | B31: Est. Import Value (USD/yr) | C31: 3. IMPORT INTELLIGENCE | E31: Import data | F31: Annual import value, all categories. | G31: 1800000
A32: AB | B32: Typical Container Type | C32: 3. IMPORT INTELLIGENCE | E32: Import data | F32: Tells you the order size to quote for. | G32: 40ft HC
A33: AC | B33: Import Frequency | C33: 3. IMPORT INTELLIGENCE | E33: Import data | F33: How often they buy — sets your follow-up rhythm. | G33: Monthly
A34: AD | B34: Last Known Shipment | C34: 3. IMPORT INTELLIGENCE | E34: Import data | F34: A buyer who shipped last month is live. One who last shipped in 2023 may not be. | G34: 18-Jul-26
A35: AE | B35: Displacement Opportunity | C35: 3. IMPORT INTELLIGENCE | E35: Judgement | F35: How realistically SACVIN can take share, given price, range and lead time. | G35: High
A36: AF | B36: Import Data Source | C36: 3. IMPORT INTELLIGENCE | E36: Dropdown | F36: Where the import figures came from. Never leave this blank if figures are filled. | G36: Volza
A37: AG | B37: Nearest Discharge Port | C37: 4. COMMERCIAL FIT | E37: Manual | F37: Drives freight cost and the transit time you can quote. | G37: Mombasa
A38: AH | B38: Preferential Access | C38: 4. COMMERCIAL FIT | E38: Dropdown | F38: Any duty relief on Nigerian origin. Verify before quoting it to a buyer. | G38: AfCFTA
A39: AI | B39: Compliance / Certification | C39: 4. COMMERCIAL FIT | E39: Claude research | F39: Destination requirements — pre-shipment inspection, marking, standards mark. | G39: PVoC required
A40: AJ | B40: Language | C40: 4. COMMERCIAL FIT | E40: Manual | F40: For catalogue, label and first-mail language. | G40: English
... A42: AL | B42: Est. Opportunity (USD/yr) | C42: 4. COMMERCIAL FIT | E42: Judgement | F42: What SACVIN could realistically win in year one. Keep it honest. | G42: 180000
...

Sheet SUMMARY
A1: LEAD LIST — AT A GLANCE
A2: =("Live from LEAD MASTER. Opened: ")&TEXT(TODAY(),"DD-MMM-YYYY") -> Live from LEAD MASTER. Opened: 26-Aug-2026
A4: THE LIST
A5: Total Leads | C5: Tier A | E5: Tier B | G5: Tier C | I5: Tier D | K5: Duplicates
A6: =COUNTA('LEAD MASTER'!$E$3:$E$402) -> 3 | C6: =COUNTIF('LEAD MASTER'!$BD$3:$BD$402,"A") -> 2 | E6: =COUNTIF('LEAD MASTER'!$BD$3:$BD$402,"B") -> 0 | G6: =COUNTIF('LEAD MASTER'!$BD$3:$BD$402,"C") -> 1 | I6: =COUNTIF('LEAD MASTER'!$BD$3:$BD$402,"D") -> 0 | K6: =COUNTIF('LEAD MASTER'!$BA$3:$BA$402,"DUPLICATE") -> 0
A9: QUALITY & OPPORTUNITY
A10: Avg Fit Score | C10: Avg Data Completeness | E10: Records under 70% complete | G10: Confirmed importers | I10: Sourcing competing origins | K10: Est. Opportunity (USD/yr)
A11: =IF(COUNT('LEAD MASTER'!$BC$3:$BC$402)=0,"-",ROUND(AVERAGE('LEAD MASTER'!$BC$3:$BC$402),1)) -> 81 | C11: =IF(COUNT('LEAD MASTER'!$AZ$3:$AZ$402)=0,"-",AVERAGE('LEAD MASTER'!$AZ$3:$AZ$402)) -> 0.94444444 | E11: =COUNTIFS('LEAD MASTER'!$AZ$3:$AZ$402,"<0.7",'LEAD MASTER'!$AZ$3:$AZ$402,"<>") -> 0 | G11: =COUNTIF('LEAD MASTER'!$U$3:$U$402,"Yes") -> 2 | I11: =COUNTIF('LEAD MASTER'!$X$3:$X$402,"Yes") -> 2 | K11: =SUM('LEAD MASTER'!$AL$3:$AL$402) -> 180000
A14: BY BUSINESS TYPE | E14: BY REGION
A15: Business Type | B15: Leads | C15: Tier A | E15: Region | F15: Leads | G15: Tier A
A16: =LISTS!$C$3 -> Importer | B16: =COUNTIF('LEAD MASTER'!$J$3:$J$402,LISTS!$C$3) -> 1 | C16: =COUNTIFS('LEAD MASTER'!$J$3:$J$402,LISTS!$C$3,'LEAD MASTER'!$BD$3:$BD$402,"A") -> 1 | E16: Central Africa | F16: =COUNTIF('LEAD MASTER'!$H$3:$H$402,$E16) -> 0 | G16: =COUNTIFS('LEAD MASTER'!$H$3:$H$402,$E16,'LEAD MASTER'!$BD$3:$BD$402,"A") -> 0
A17: =LISTS!$C$4 -> Distributor | B17: =COUNTIF('LEAD MASTER'!$J$3:$J$402,LISTS!$C$4) -> 1 | C17: =COUNTIFS('LEAD MASTER'!$J$3:$J$402,LISTS!$C$4,'LEAD MASTER'!$BD$3:$BD$402,"A") -> 1 | E17: Central America & Caribbean | F17: =COUNTIF('LEAD MASTER'!$H$3:$H$402,$E17) -> 0 | G17: =COUNTIFS('LEAD MASTER'!$H$3:$H$402,$E17,'LEAD MASTER'!$BD$3:$BD$402,"A") -> 0
A18: =LISTS!$C$5 -> Wholesaler | B18: =COUNTIF('LEAD MASTER'!$J$3:$J$402,LISTS!$C$5) -> 1 | C18: =COUNTIFS('LEAD MASTER'!$J$3:$J$402,LISTS!$C$5,'LEAD MASTER'!$BD$3:$BD$402,"A") -> 0 | E18: East Africa | F18: =COUNTIF('LEAD MASTER'!$H$3:$H$402,$E18) -> 1 | G18: =COUNTIFS('LEAD MASTER'!$H$3:$H$402,$E18,'LEAD MASTER'!$BD$3:$BD$402,"A") -> 1
A19: =LISTS!$C$6 -> Retail chain | B19: =COUNTIF('LEAD MASTER'!$J$3:$J$402,LISTS!$C$6) -> 0 | C19: =COUNTIFS('LEAD MASTER'!$J$3:$J$402,LISTS!$C$6,'LEAD MASTER'!$BD$3:$BD$402,"A") -> 0 | E19: East Asia | F19: =COUNTIF('LEAD MASTER'!$H$3:$H$402,$E19) -> 0 | G19: =COUNTIFS('LEAD MASTER'!$H$3:$H$402,$E19,'LEAD MASTER'!$BD$3:$BD$402,"A") -> 0
A20: =LISTS!$C$7 -> Supermarket group | B20: =COUNTIF('LEAD MASTER'!$J$3:$J$402,LISTS!$C$7) -> 0 | C20: =COUNTIFS('LEAD MASTER'!$J$3:$J$402,LISTS!$C$7,'LEAD MASTER'!$BD$3:$BD$402,"A") -> 0 | E20: Eastern Europe | F20: =COUNTIF('LEAD MASTER'!$H$3:$H$402,$E20) -> 0 | G20: =COUNTIFS('LEAD MASTER'!$H$3:$H$402,$E20,'LEAD MASTER'!$BD$3:$BD$402,"A") -> 0
A21: =LISTS!$C$8 -> Cash & carry | B21: =COUNTIF('LEAD MASTER'!$J$3:$J$402,LISTS!$C$8) -> 0 | C21: =COUNTIFS('LEAD MASTER'!$J$3:$J$402,LISTS!$C$8,'LEAD MASTER'!$BD$3:$BD$402,"A") -> 0 | E21: Indian Subcontinent | F21: =COUNTIF('LEAD MASTER'!$H$3:$H$402,$E21) -> 0 | G21: =COUNTIFS('LEAD MASTER'!$H$3:$H$402,$E21,'LEAD MASTER'!$BD$3:$BD$402,"A") -> 0
A22: =LISTS!$C$9 -> Buying house / Sourcing agent | B22: =COUNTIF('LEAD MASTER'!$J$3:$J$402,LISTS!$C$9) -> 0 | C22: =COUNTIFS('LEAD MASTER'!$J$3:$J$402,LISTS!$C$9,'LEAD MASTER'!$BD$3:$BD$402,"A") -> 0 | E22: Middle East / Gulf | F22: =COUNTIF('LEAD MASTER'!$H$3:$H$402,$E22) -> 1 | G22: =COUNTIFS('LEAD MASTER'!$H$3:$H$402,$E22,'LEAD MASTER'!$BD$3:$BD$402,"A") -> 1
A23: =LISTS!$C$10 -> E-commerce | B23: =COUNTIF('LEAD MASTER'!$J$3:$J$402,LISTS!$C$10) -> 0 | C23: =COUNTIFS('LEAD MASTER'!$J$3:$J$402,LISTS!$C$10,'LEAD MASTER'!$BD$3:$BD$402,"A") -> 0 | E23: North Africa | F23: =COUNTIF('LEAD MASTER'!$H$3:$H$402,$E23) -> 0 | G23: =COUNTIFS('LEAD MASTER'!$H$3:$H$402,$E23,'LEAD MASTER'!$BD$3:$BD$402,"A") -> 0
A24: =LISTS!$C$11 -> Agent / Broker | B24: =COUNTIF('LEAD MASTER'!$J$3:$J$402,LISTS!$C$11) -> 0 | C24: =COUNTIFS('LEAD MASTER'!$J$3:$J$402,LISTS!$C$11,'LEAD MASTER'!$BD$3:$BD$402,"A") -> 0 | E24: North America | F24: =COUNTIF('LEAD MASTER'!$H$3:$H$402,$E24) -> 0 | G24: =COUNTIFS('LEAD MASTER'!$H$3:$H$402,$E24,'LEAD MASTER'!$BD$3:$BD$402,"A") -> 0
A25: =LISTS!$C$12 -> Manufacturer (complementary range) | B25: =COUNTIF('LEAD MASTER'!$J$3:$J$402,LISTS!$C$12) -> 0 | C25: =COUNTIFS('LEAD MASTER'!$J$3:$J$402,LISTS!$C$12,'LEAD MASTER'!$BD$3:$BD$402,"A") -> 0 | E25: Oceania | F25: =COUNTIF('LEAD MASTER'!$H$3:$H$402,$E25) -> 1 | G25: =COUNTIFS('LEAD MASTER'!$H$3:$H$402,$E25,'LEAD MASTER'!$BD$3:$BD$402,"A") -> 0
E26: South America | F26: =COUNTIF('LEAD MASTER'!$H$3:$H$402,$E26) -> 0 | G26: =COUNTIFS('LEAD MASTER'!$H$3:$H$402,$E26,'LEAD MASTER'!$BD$3:$BD$402,"A") -> 0
E27: South East Asia | F27: =COUNTIF('LEAD MASTER'!$H$3:$H$402,$E27) -> 0 | G27: =COUNTIFS('LEAD MASTER'!$H$3:$H$402,$E27,'LEAD MASTER'!$BD$3:$BD$402,"A") -> 0
E28: Southern Africa | F28: =COUNTIF('LEAD MASTER'!$H$3:$H$402,$E28) -> 0 | G28: =COUNTIFS('LEAD MASTER'!$H$3:$H$402,$E28,'LEAD MASTER'!$BD$3:$BD$402,"A") -> 0
E29: West Africa | F29: =COUNTIF('LEAD MASTER'!$H$3:$H$402,$E29) -> 0 | G29: =COUNTIFS('LEAD MASTER'!$H$3:$H$402,$E29,'LEAD MASTER'!$BD$3:$BD$402,"A") -> 0
E30: Western Europe | F30: =COUNTIF('LEAD MASTER'!$H$3:$H$402,$E30) -> 0 | G30: =COUNTIFS('LEAD MASTER'!$H$3:$H$402,$E30,'LEAD MASTER'!$BD$3:$BD$402,"A") -> 0
